Workbook

Sheet CONSOLIDADO
A1: CUERPO DE BOMBEROS VOLUNTARIOS, LA UNIÓN, VALLE DEL CAUCA REPORTE DE EMERGENCIAS
A2: DURANTE EL MES DE AGOSTO DEL 2026
A3: EMERGENCIAS | B3: CANTIDAD | C3: % INCIDENCIA
A4: CAÍDA / CORTES DE ARBOL | B4: =COUNTIF(DATOS!$B:$B,CONSOLIDADO!$A$4:$A$26) -> 1 | C4: =B4/$B$27 -> 0.0028169014
A5: CONTROL DE ABEJAS | B5: =COUNTIF(DATOS!$B:$B,CONSOLIDADO!$A$4:$A$26) -> 2 | C5: =B5/$B$27 -> 0.0056338028
A6: CONTROL DE AVISPAS | B6: =COUNTIF(DATOS!$B:$B,CONSOLIDADO!$A$4:$A$26) -> 1 | C6: =B6/$B$27 -> 0.0028169014
A7: CAÍDA DE CUERDAS | B7: =COUNTIF(DATOS!$B:$B,CONSOLIDADO!$A$4:$A$26) -> 3 | C7: =B7/$B$27 -> 0.0084507042
A8: CORTO CIRCUITO | B8: =COUNTIF(DATOS!$B:$B,CONSOLIDADO!$A$4:$A$26) -> 3 | C8: =B8/$B$27 -> 0.0084507042
A9: COLAPSO DE ESTRUCTURAS | B9: =COUNTIF(DATOS!$B:$B,CONSOLIDADO!$A$4:$A$26) -> 2 | C9: =B9/$B$27 -> 0.0056338028
A10: CAPACITACIONES | B10: =COUNTIF(DATOS!$B:$B,CONSOLIDADO!$A$4:$A$26) -> 0 | C10: =B10/$B$27 -> 0
A11: EXTRICACIÓN VEHICULAR | B11: =COUNTIF(DATOS!$B:$B,CONSOLIDADO!$A$4:$A$26) -> 0 | C11: =B11/$B$27 -> 0
A12: FUGA DE GAS NATURAL | B12: =COUNTIF(DATOS!$B:$B,CONSOLIDADO!$A$4:$A$26) -> 4 | C12: =B12/$B$27 -> 0.011267606
A13: FUGA DE GAS GLP | B13: =COUNTIF(DATOS!$B:$B,CONSOLIDADO!$A$4:$A$26) -> 0 | C13: =B13/$B$27 -> 0
A14: INCENDIO FORESTAL | B14: =COUNTIF(DATOS!$B:$B,CONSOLIDADO!$A$4:$A$26) -> 7 | C14: =B14/$B$27 -> 0.01971831
A15: INCENDIO ESTRUCTURAL | B15: =COUNTIF(DATOS!$B:$B,CONSOLIDADO!$A$4:$A$26) -> 1 | C15: =B15/$B$27 -> 0.0028169014
... A26: VISITAS DE SEGURIDAD | B26: =COUNTIF(DATOS!$B:$B,CONSOLIDADO!$A$4:$A$26) -> 0 | C26: =B26/$B$27 -> 0
A27: TOTAL | B27: =SUM(B3:B26) -> 355 | C27: =B27/$B$27 -> 1

Sheet DATOS
A1: TIPO DE INCIDENTE | B1: INCIDENTES Y ACTIVIDADES | C1: CANTIDAD DE | D1: DÍA DEL EVENTO | E1: DURACIÓN DEL EVENTO | F1: DIRECCIÓN O LUGAR DE REFERENCIA | G1: BARRIO CORREGIMIENTO O VEREDA | H1: DESCRIPCIÓN DEL EVENTO | I1: AREA AFECTADA (SOLO SI APLICA) | J1: N° DE UNIDADES QUE ASISTIERON | K1: VEHÍCULO | L1: COORDENADAS | Q1: BUSCAR | R1: CAÍDA / CORTES DE ARBOL | S1: CONTROL DE ABEJAS | T1: CONTROL DE AVISPAS | U1: CAÍDA DE CUERDAS | V1: CORTO CIRCUITO | W1: COLAPSO DE ESTRUCTURAS | X1: CAPACITACIONES | Y1: EXTRICACIÓN VEHICULAR | Z1: FUGA DE GAS NATURAL | AA1: FUGA DE GAS GLP | AB1: INCENDIO FORESTAL | AC1: INCENDIO ESTRUCTURAL | AD1: INCENDIO VEHICULAR | AE1: INUNDACIÓN | AF1: LABORES DE PREVENCION O ACOMPAÑAMIENTO EN GESTION DEL RIESGO | AG1: MATERIALES PELIGROSOS / DERRAMES | AH1: PRIMEROS AUXILIOS | AI1: RESCATE DE PERSONA / PARAPENTE | AJ1: RESCATE DE ANIMAL | AK1: REUNIÓN EN LA ALCALDÍA | AL1: REUNIONES DE SERVICIO SOCIAL | AM1: SUMINISTROS DE AGUA | AN1: VISITAS DE SEGURIDAD
C2: RESCATE DE ANIMAL
A3: AGOSTO
A4: OTROS | B4: PRIMEROS AUXILIOS | C4: =COUNTIF(B4:B358,C2) -> 2 | D4: 46236 | E4: 1 HORA Y 40 MINUTOS | F4: EN LA ENTRADA A CORSEGA | G4: N/A | H4: N/A | I4: N/A | J4: 3 | K4: B-2 | L4: N/A
A5: INCENDIOS | B5: INCENDIO VEHICULAR | D5: 46236 | E5: 41 MINUTOS | F5: VÍA LA UNIÓN - LA VICTORIA CERCA A ASORUT | H5: AGENTES DE TRANSITO REPORTAR EL INCENDIO DE UN VEHÍCULO TIPO MOTOCICLETA, SALEN 3 UNIDADES PARA HACER LIQUIDACI{ON DEL FUEGO E INFRIAMENTO DEL PERÍMETRO AFECTADO. | I5: N/A | J5: 3 | K5: B-4 | L5: N/A
A6: INCENDIOS | B6: INCENDIO FORESTAL | D6: 46236 | E6: 1 HORA | F6: LAS BRISAS | G6: LAS BRISAS | H6: QUEMAS DE UNAS TABLAS DE MADERA POR UN DESCONOCIDO | I6: 10 MTS | J6: 2 | K6: B-2 | L6: N/A
A7: INCENDIOS | B7: CORTO CIRCUITO | D7: 46240 | E7: 1 HORA | F7: CLL 13 CON CR 14 | G7: CENTRO | H7: INFORMAN DE UNA EXPLOSION EN LA CAJA DE CABLEADO ELECTRICO | I7: . | J7: 4 | K7: B-2 | L7: .
A8: OTROS | B8: CONTROL DE ABEJAS | D8: 46240 | E8: 1 HORA | F8: SAN LUIS | G8: SAN LUIS | H8: INFORMAN DE UN ATAQUE DE ABEJAS CON UNA PERSONA LESIONADA | I8: . | J8: 3 | K8: B-3 | L8: .
A9: INCENDIOS | B9: CAÍDA DE CUERDAS | D9: 46240 | E9: 45 MNTOS | F9: TRANSV 13 VIA A LAS CINTAS | G9: LAS PALMAS | H9: CABLE ELECTRICO QUE CAE, PRODUCIENDO CHISPAS E INICIANDO UN INCENDIO EN PASTIZAL | I9: 50 M/2 APROXI | J9: 4 | K9: B-2 | L9: *
A10: INCENDIOS | B10: INCENDIO FORESTAL | D10: 46242 | E10: 2.30 HORAS | F10: LINDEROS FINCA GALLINERO | G10: LA ISLA | H10: INCENDIO DE COVERTURA VEGETAL PASTO Y MALEZA, QUEMA SALTEADA POR SECTORES | I10: 4 HECTAREAS APROX | J10: 5 | K10: B-4, OTROS | L10: 30.32 N 4;76 W
A11: INCENDIOS | B11: INCENDIO FORESTAL | D11: 46244 | E11: 1 HORA | F11: VEREDA LA ISLA | G11: LA ISLA | H11: INFORMAN DE UNA QUEMA EN ZONA VEJETAL | I11: .100MTR 2 | J11: 6 | K11: B-2, L-1 | L11: .
A12: INCENDIOS | B12: CORTO CIRCUITO | D12: 46244 | E12: 1 HORA | F12: CORCEGA | G12: COCEGA | H12: INFORMAN DE UN CORTI CIRCUITO EN LA CAJA DE CABLES ELECTRICOS QUE ESTAN CERCA DE ARBOLES Y PUEDE INICIAR CON UN INCENDIO | I12: . | J12: 7 | K12: B-4, L-1 | L12: .
A13: MATERIALES PELIGROSOS | B13: FUGA DE GAS NATURAL | D13: 46244 | E13: 1 HORA | F13: CR 15 CON CL 19 ESQUINA | G13: LA CRUZ | H13: INFORMAN DE UN FUERTE OLOR A GAS | I13: . | J13: 2 | K13: B-4 | L13: .
A14: OTROS | B14: LABORES DE PREVENCION O ACOMPAÑAMIENTO EN GESTION DEL RIESGO | D14: 46244 | E14: 1 HORA | F14: CR 16 19 91 | G14: SAN PEDRO | H14: INFORMAN DE UNA EDIFICACION QUE EMITE RUIDOS Y ESTA CON GRAN RIESGO DE COLAPSO | I14: . | J14: 2 | K14: L-2 | L14: .
A15: RESCATES, BUSQUEDA Y RESCATE, OTROS | B15: COLAPSO DE ESTRUCTURAS | D15: 46244 | E15: 12 HORAS | F15: ZONA URBANA DE LA UNION VALLE | H15: VERIFICACION DE DAÑOS Y/O BUSQUEDA Y RESCATE DE PERSONAS POR TERREMOTO | I15: N/A | J15: 33 | K15: B-2, B-3, B-4, L-1, L-2, L-3, OTROS | L15: N/A
A16: OTROS | B16: COLAPSO DE ESTRUCTURAS | D16: 46244 | E16: 1 HORA | F16: CR 16 19 100 | G16: SAN PEDRO | H16: EVALUACION DE AFECTACION A LA ESTRUCTURA | I16: . | J16: 4 | K16: L-1 | L16: .
A17: OTROS | B17: LABORES DE PREVENCION O ACOMPAÑAMIENTO EN GESTION DEL RIESGO | D17: 46244 | E17: 30 MINUTOS | F17: CRA 19 C #19-04 | G17: LA HABANA - URBANIZACION CAMINOS | H17: ANDRES FELIPE DIEZ, C.C: 1112630292, CEL: 3125190481. VIVIENDA DE DOS PISOS CON DAÑOS ESTRUCTURALES | I17: N/A | J17: 8 | K17: B-3 | L17: N/A
A18: OTROS | B18: LABORES DE PREVENCION O ACOMPAÑAMIENTO EN GESTION DEL RIESGO | D18: 46244 | E18: 30 MINUTOS | F18: CRA 19 D # 19-63 | G18: URBANIZACION CAMINOS | H18: GILDARDO RENGIFO, C.C: 18513953, CEL: 3217018236. VIVIENDA CON COLAPSO DE TECHO | I18: N/A | J18: 8 | K18: B-3 | L18: N/A
A19: OTROS | B19: LABORES DE PREVENCION O ACOMPAÑAMIENTO EN GESTION DEL RIESGO | D19: 46244 | E19: 30 MINUTOS | F19: CRA 19 D #19-09 | G19: URBANIZACION CAMINOS | H19: RUBIELA PEREZ, C.C: 29613954, CEL: 3128240451-3185385634. SEPARACION DE LA CUBIERTA DEL TECHO | J19: 8 | K19: B-3
A20: OTROS | B20: LABORES DE PREVENCION O ACOMPAÑAMIENTO EN GESTION DEL RIESGO | D20: 46244 | E20: 30 MINUTOS | F20: CRA 19 D #19-15 | H20: EDILMA FLORES, C.C: 38892573, CEL: 3148960797. AFECTACION EN LA CUBIERTA DEL TECHO Y PAREDES AGRIETADAS | J20: 8 | K20: B-3
A21: OTROS | B21: LABORES DE PREVENCION O ACOMPAÑAMIENTO EN GESTION DEL RIESGO | D21: 46244 | E21: 30 MINUTOS | F21: CRA 19 C # 19-10 | G21: URBANIZACION CAMINOS | H21: DANIELA CORREA, C.C: 11126311863, CEL: 3178583900. VIVIENDA CON PAREDES AGRIETADAS | J21: 8 | K21: B-3
A22: OTROS | B22: LABORES DE PREVENCION O ACOMPAÑAMIENTO EN GESTION DEL RIESGO | D22: 46244 | E22: 30 MINUTOS | F22: CRA 15 # 22-02 | G22: SAN PEDRO | H22: CRISTINA VELEZ, C.C 66750742, CEL: 3102160599. CAIDA TOTAL DE EDIFICACION | J22: 8 | K22: B-3
A23: OTROS | B23: LABORES DE PREVENCION O ACOMPAÑAMIENTO EN GESTION DEL RIESGO | D23: 46244 | E23: 30 MINUTOS | F23: CRA 20 # 19-04 | G23: URBANIZACION CAMINOS | H23: MARCO AURELIO RAMIREZ, C.C 15599667, CEL: 3177575131. DILATACION DE PAREDES Y TECHO | J23: 8 | K23: B-3
A24: OTROS | B24: LABORES DE PREVENCION O ACOMPAÑAMIENTO EN GESTION DEL RIESGO | D24: 46244 | E24: 30 MINUTOS | F24: CRA 20 # 19-22 | G24: URBANIZACION CAMINOS | H24: LUIS GONZAGA LOPEZ, C.C: 1112619461, CEL: 3151924116. DILATACION DE PAREDES Y VIGAS DEL SEGUNDO PISO AGRIETADAS | J24: 8 | K24: B-3
A25: OTROS | B25: LABORES DE PREVENCION O ACOMPAÑAMIENTO EN GESTION DEL RIESGO | D25: 46244 | E25: 30 MINUTOS | F25: CRA 20 #19-64 | G25: URBANIZACION CAMINOS | H25: LEIDY CARDONA GAÑAN, C.C: 1000364885, CEL: 3173213134. CAIDA CONSIDERABLE DE TEJA DE BARRO EN TECHO | J25: 8 | K25: B-3
A26: OTROS | B26: LABORES DE PREVENCION O ACOMPAÑAMIENTO EN GESTION DEL RIESGO | D26: 46244 | E26: 30 MINUTOS | F26: CRA 20 # 18-241 | G26: URBANIZACION CAMINOS | H26: ALEIDA RIVERA GUERRERO, C.C 41895449, CEL: 3217769241. DAÑO EN TECHO Y PAREDES AGRIETADAS | J26: 8 | K26: B-3
A27: OTROS | B27: LABORES DE PREVENCION O ACOMPAÑAMIENTO EN GESTION DEL RIESGO | D27: 46244 | E27: 30 MINUTOS | F27: CRA 16 #19-20 | G27: SAN PEDRO | H27: CRISTIAN CAMILO GALVIS, C.C 1112629109, CEL: 3215905304. COLAPSO DE TECHO Y PAREDES | J27: 8 | K27: B-3
A28: OTROS | B28: LABORES DE PREVENCION O ACOMPAÑAMIENTO EN GESTION DEL RIESGO | D28: 46244 | E28: 30 MINUTOS | F28: CRA 16 # 19-44 | G28: SAN PEDRO | H28: VIRGELINA RUBIO, C.C 66751468, CEL: 3163240509. DAÑOS ESTRUCTURALES | J28: 8 | K28: B-3
A29: OTROS | B29: LABORES DE PREVENCION O ACOMPAÑAMIENTO EN GESTION DEL RIESGO | D29: 46244 | E29: 30 MINUTOS | F29: CRA 16#19-66 | G29: SAN PEDRO | H29: JAIRO GALEANO, C.C: 94450938, CEL: 3104732455. UNAS PAREDES AGRIETADAS Y OTRAS COLAPSADAS | J29: 8 | K29: B-3
A30: OTROS | B30: LABORES DE PREVENCION O ACOMPAÑAMIENTO EN GESTION DEL RIESGO | D30: 46244 | E30: 30 MINUTOS | F30: CRA 16 #19-66 | G30: SAN PEDRO | H30: LEONIDAS CABALLERO, C.C: 6356187, CEL: 3172559929. DAÑOS ESTRUCTULARES | J30: 8 | K30: B-3
A31: OTROS | B31: LABORES DE PREVENCION O ACOMPAÑAMIENTO EN GESTION DEL RIESGO | D31: 46244 | E31: 30 MINUTOS | F31: CRA 16#19-82 | G31: SAN PEDRO | H31: LUZ ENAY TORO VALENCIA, C.C:66752243, CEL: 3103867057. DAÑO EN TECHO, PAREDES Y COLUMNAS AGRIETADAS | J31: 8 | K31: B-3
A32: OTROS | B32: LABORES DE PREVENCION O ACOMPAÑAMIENTO EN GESTION DEL RIESGO | D32: 46244 | E32: 30 MINUTOS | F32: CRA 16 # 19-100 | G32: SAN PADRO | H32: EDIFICIO DE TRES PISOS CON FALLAS ESTRUCTURALES, INHABITABLE | J32: 8 | K32: B-3
... A108: OTROS | B108: LABORES DE PREVENCION O ACOMPAÑAMIENTO EN GESTION DEL RIESGO | D108: 46244 | E108: 1 HORA | F108: CLL 12 # 20-202 APTO 1 | G108: — | H108: HEIDY HINCAPIÉ HENAO – Cel. 3128719472 – Colapso de techo, segundo piso. | J108: 8 | K108: B-3
A109: OTROS | B109: LABORES DE PREVENCION O ACOMPAÑAMIENTO EN GESTION DEL RIESGO | D109: 46244 | E109: 30 MINUTOS | G109: — | H109: FAREN TATIANA HINCAPIÉ – Cel. 3154517082 – Colapso de techo. | J109: 8 | K109: B-3
A110: OTROS | B110: LABORES DE PREVENCION O ACOMPAÑAMIENTO EN GESTION DEL RIESGO | D110: 46244 | E110: 30 MINUTOS | F110: CRA 12 # 11-58 | G110: BELÉN | H110: AMPARO OSPINA OCAMPO – Cel. 32006897815 – Infraestructura debilitada. | J110: 5 | K110: L-2
A111: OTROS | B111: LABORES DE PREVENCION O ACOMPAÑAMIENTO EN GESTION DEL RIESGO | D111: 46244 | E111: 1 HORA | F111: CRA 12 # 12-27 | G111: — | H111: CARLOS ALBERTO TAMAYO – Cel. 3155508915 – Colapso de techo con caída de material/escombros. | J111: 5 | K111: L-2
A112: OTROS | B112: LABORES DE PREVENCION O ACOMPAÑAMIENTO EN GESTION DEL RIESGO | D112: 46244 | E112: 30 MINUTOS | F112: CRA 12 # 12-35 | G112: — | H112: ROSA DORIS OSORIO – Cel. 3148195689 – Colapso de techo. | J112: 5 | K112: L-2
A113: OTROS | B113: LABORES DE PREVENCION O ACOMPAÑAMIENTO EN GESTION DEL RIESGO | D113: 46244 | E113: 30 MINUTOS | F113: CRA 14 # 13-08 | G113: — | H113: Colapso estructural parcial. | J113: 5 | K113: L-2
A114: OTROS | B114: LABORES DE PREVENCION O ACOMPAÑAMIENTO EN GESTION DEL RIESGO | D114: 46244 | E114: 1 HORA | F114: CRA 15 # 12-34 | G114: — | H114: Colapso de fachada y posible colapso de techo. | J114: 5 | K114: L-2
A115: OTROS | B115: LABORES DE PREVENCION O ACOMPAÑAMIENTO EN GESTION DEL RIESGO | D115: 46244 | E115: 1 HORA | F115: CRA 13 # 12-71 ESQUINA | G115: — | H115: Colapso de techo e infraestructura debilitada. | J115: 5 | K115: L-2
...
