Workbook

Sheet CONSOLIDADO 5 AÑOS
A1: CUERPO DE BOMBEROS VOLUNTARIOS, LA UNIÓN, VALLE DEL CAUCA INFORME DE ACTIVIDADES DESDE EL AÑO 2021 HASTA EL 2025
A2: EMERGENCIAS | B2: CANTIDAD | C2: % INCIDENCIA
A3: CAÍDA / CORTES DE ARBOL | B3: =COUNTIF('2021'!B:B,'CONSOLIDADO 5 AÑOS'!A3) + COUNTIF('2022'!B:B,'CONSOLIDADO 5 AÑOS'!A3) + COUNTIF('2023'!B:B,'CONSOLIDADO 5 AÑOS'!A3) + COUNTIF('2024'!B:B,'CONSOLIDADO 5 AÑOS'!A3) + COUNTIF('2025'!B:B,'CONSOLIDADO 5 AÑOS'!A3) -> 103 | C3: =B3/$B$26 -> 0.056937535
A4: CONTROL DE ABEJAS | B4: =COUNTIF('2021'!B:B,'CONSOLIDADO 5 AÑOS'!A4) + COUNTIF('2022'!B:B,'CONSOLIDADO 5 AÑOS'!A4) + COUNTIF('2023'!B:B,'CONSOLIDADO 5 AÑOS'!A4) + COUNTIF('2024'!B:B,'CONSOLIDADO 5 AÑOS'!A4) + COUNTIF('2025'!B:B,'CONSOLIDADO 5 AÑOS'!A4) -> 205 | C4: =B4/$B$26 -> 0.11332228
A5: CONTROL DE AVISPAS | B5: =COUNTIF('2021'!B:B,'CONSOLIDADO 5 AÑOS'!A5) + COUNTIF('2022'!B:B,'CONSOLIDADO 5 AÑOS'!A5) + COUNTIF('2023'!B:B,'CONSOLIDADO 5 AÑOS'!A5) + COUNTIF('2024'!B:B,'CONSOLIDADO 5 AÑOS'!A5) + COUNTIF('2025'!B:B,'CONSOLIDADO 5 AÑOS'!A5) -> 20 | C5: =B5/$B$26 -> 0.011055832
A6: CAÍDA DE CUERDAS | B6: =COUNTIF('2021'!B:B,'CONSOLIDADO 5 AÑOS'!A6) + COUNTIF('2022'!B:B,'CONSOLIDADO 5 AÑOS'!A6) + COUNTIF('2023'!B:B,'CONSOLIDADO 5 AÑOS'!A6) + COUNTIF('2024'!B:B,'CONSOLIDADO 5 AÑOS'!A6) + COUNTIF('2025'!B:B,'CONSOLIDADO 5 AÑOS'!A6) -> 17 | C6: =B6/$B$26 -> 0.0093974572
A7: CORTO CIRCUITO | B7: =COUNTIF('2021'!B:B,'CONSOLIDADO 5 AÑOS'!A7) + COUNTIF('2022'!B:B,'CONSOLIDADO 5 AÑOS'!A7) + COUNTIF('2023'!B:B,'CONSOLIDADO 5 AÑOS'!A7) + COUNTIF('2024'!B:B,'CONSOLIDADO 5 AÑOS'!A7) + COUNTIF('2025'!B:B,'CONSOLIDADO 5 AÑOS'!A7) -> 41 | C7: =B7/$B$26 -> 0.022664456
A8: COLAPSO DE ESTRUCTURAS | B8: =COUNTIF('2021'!B:B,'CONSOLIDADO 5 AÑOS'!A8) + COUNTIF('2022'!B:B,'CONSOLIDADO 5 AÑOS'!A8) + COUNTIF('2023'!B:B,'CONSOLIDADO 5 AÑOS'!A8) + COUNTIF('2024'!B:B,'CONSOLIDADO 5 AÑOS'!A8) + COUNTIF('2025'!B:B,'CONSOLIDADO 5 AÑOS'!A8) -> 5 | C8: =B8/$B$26 -> 0.002763958
A9: CAPACITACIONES | B9: =COUNTIF('2021'!B:B,'CONSOLIDADO 5 AÑOS'!A9) + COUNTIF('2022'!B:B,'CONSOLIDADO 5 AÑOS'!A9) + COUNTIF('2023'!B:B,'CONSOLIDADO 5 AÑOS'!A9) + COUNTIF('2024'!B:B,'CONSOLIDADO 5 AÑOS'!A9) + COUNTIF('2025'!B:B,'CONSOLIDADO 5 AÑOS'!A9) -> 11 | C9: =B9/$B$26 -> 0.0060807076
A10: EXTRICACIÓN VEHICULAR | B10: =COUNTIF('2021'!B:B,'CONSOLIDADO 5 AÑOS'!A10) + COUNTIF('2022'!B:B,'CONSOLIDADO 5 AÑOS'!A10) + COUNTIF('2023'!B:B,'CONSOLIDADO 5 AÑOS'!A10) + COUNTIF('2024'!B:B,'CONSOLIDADO 5 AÑOS'!A10) + COUNTIF('2025'!B:B,'CONSOLIDADO 5 AÑOS'!A10) -> 13 | C10: =B10/$B$26 -> 0.0071862908
A11: FUGA DE GAS NATURAL | B11: =COUNTIF('2021'!B:B,'CONSOLIDADO 5 AÑOS'!A11) + COUNTIF('2022'!B:B,'CONSOLIDADO 5 AÑOS'!A11) + COUNTIF('2023'!B:B,'CONSOLIDADO 5 AÑOS'!A11) + COUNTIF('2024'!B:B,'CONSOLIDADO 5 AÑOS'!A11) + COUNTIF('2025'!B:B,'CONSOLIDADO 5 AÑOS'!A11) -> 79 | C11: =B11/$B$26 -> 0.043670536
A12: FUGA DE GAS GLP | B12: =COUNTIF('2021'!B:B,'CONSOLIDADO 5 AÑOS'!A12) + COUNTIF('2022'!B:B,'CONSOLIDADO 5 AÑOS'!A12) + COUNTIF('2023'!B:B,'CONSOLIDADO 5 AÑOS'!A12) + COUNTIF('2024'!B:B,'CONSOLIDADO 5 AÑOS'!A12) + COUNTIF('2025'!B:B,'CONSOLIDADO 5 AÑOS'!A12) -> 6 | C12: =B12/$B$26 -> 0.0033167496
A13: INCENDIO FORESTAL | B13: =COUNTIF('2021'!B:B,'CONSOLIDADO 5 AÑOS'!A13) + COUNTIF('2022'!B:B,'CONSOLIDADO 5 AÑOS'!A13) + COUNTIF('2023'!B:B,'CONSOLIDADO 5 AÑOS'!A13) + COUNTIF('2024'!B:B,'CONSOLIDADO 5 AÑOS'!A13) + COUNTIF('2025'!B:B,'CONSOLIDADO 5 AÑOS'!A13) -> 182 | C13: =B13/$B$26 -> 0.10060807
A14: INCENDIO ESTRUCTURAL | B14: =COUNTIF('2021'!B:B,'CONSOLIDADO 5 AÑOS'!A14) + COUNTIF('2022'!B:B,'CONSOLIDADO 5 AÑOS'!A14) + COUNTIF('2023'!B:B,'CONSOLIDADO 5 AÑOS'!A14) + COUNTIF('2024'!B:B,'CONSOLIDADO 5 AÑOS'!A14) + COUNTIF('2025'!B:B,'CONSOLIDADO 5 AÑOS'!A14) -> 46 | C14: =B14/$B$26 -> 0.025428413
... A25: VISITAS DE SEGURIDAD | B25: =COUNTIF('2021'!B:B,'CONSOLIDADO 5 AÑOS'!A25) + COUNTIF('2022'!B:B,'CONSOLIDADO 5 AÑOS'!A25) + COUNTIF('2023'!B:B,'CONSOLIDADO 5 AÑOS'!A25) + COUNTIF('2024'!B:B,'CONSOLIDADO 5 AÑOS'!A25) + COUNTIF('2025'!B:B,'CONSOLIDADO 5 AÑOS'!A25) -> 415 | C25: =B25/$B$26 -> 0.22940851
A26: TOTAL | B26: =SUM(B3:B25) -> 1809 | C26: =B26/$B$26 -> 1
D43: CANTIDAD DE EMERGENCIAS Y ACTIVIDADES ANUALES
D44: 2021 | E44: 2022 | F44: 2023 | G44: 2024 | H44: 2025 | I44: TOTAL | J44: PROM. X AÑO
D45: ='2021'!B331 -> 316 | E45: ='2022'!B485 -> 470 | F45: ='2023'!B404 -> 389 | G45: ='2024'!B413 -> 398 | H45: ='2025'!B251 -> 236 | I45: =SUM(D45:H45) -> 1809 | J45: =AVERAGE(D45:H45) -> 361.8

Sheet CONSOLIDADO AÑO 2026
A1: CUERPO DE BOMBEROS VOLUNTARIOS, LA UNIÓN, VALLE DEL CAUCA INFORME DE ACTIVIDADES EN LO CORRIDO DEL AÑO 2026
A2: EMERGENCIAS | B2: CANTIDAD | C2: % INCIDENCIA
A3: CAÍDA / CORTES DE ARBOL | B3: =COUNTIF('2026'!$B:$B, 'CONSOLIDADO AÑO 2026'!$A$3:$A$25) -> 24 | C3: =B3/$B$26 -> 0.043875686
A4: CONTROL DE ABEJAS | B4: =COUNTIF('2026'!$B:$B, 'CONSOLIDADO AÑO 2026'!$A$3:$A$25) -> 25 | C4: =B4/$B$26 -> 0.045703839
A5: CONTROL DE AVISPAS | B5: =COUNTIF('2026'!$B:$B, 'CONSOLIDADO AÑO 2026'!$A$3:$A$25) -> 6 | C5: =B5/$B$26 -> 0.010968921
A6: CAÍDA DE CUERDAS | B6: =COUNTIF('2026'!$B:$B, 'CONSOLIDADO AÑO 2026'!$A$3:$A$25) -> 4 | C6: =B6/$B$26 -> 0.0073126143
A7: CORTO CIRCUITO | B7: =COUNTIF('2026'!$B:$B, 'CONSOLIDADO AÑO 2026'!$A$3:$A$25) -> 8 | C7: =B7/$B$26 -> 0.014625229
A8: COLAPSO DE ESTRUCTURAS | B8: =COUNTIF('2026'!$B:$B, 'CONSOLIDADO AÑO 2026'!$A$3:$A$25) -> 3 | C8: =B8/$B$26 -> 0.0054844607
A9: CAPACITACIONES | B9: =COUNTIF('2026'!$B:$B, 'CONSOLIDADO AÑO 2026'!$A$3:$A$25) -> 0 | C9: =B9/$B$26 -> 0
A10: EXTRICACIÓN VEHICULAR | B10: =COUNTIF('2026'!$B:$B, 'CONSOLIDADO AÑO 2026'!$A$3:$A$25) -> 0 | C10: =B10/$B$26 -> 0
A11: FUGA DE GAS NATURAL | B11: =COUNTIF('2026'!$B:$B, 'CONSOLIDADO AÑO 2026'!$A$3:$A$25) -> 23 | C11: =B11/$B$26 -> 0.042047532
A12: FUGA DE GAS GLP | B12: =COUNTIF('2026'!$B:$B, 'CONSOLIDADO AÑO 2026'!$A$3:$A$25) -> 1 | C12: =B12/$B$26 -> 0.0018281536
A13: INCENDIO FORESTAL | B13: =COUNTIF('2026'!$B:$B, 'CONSOLIDADO AÑO 2026'!$A$3:$A$25) -> 42 | C13: =B13/$B$26 -> 0.07678245
A14: INCENDIO ESTRUCTURAL | B14: =COUNTIF('2026'!$B:$B, 'CONSOLIDADO AÑO 2026'!$A$3:$A$25) -> 13 | C14: =B14/$B$26 -> 0.023765996
... A25: VISITAS DE SEGURIDAD | B25: =COUNTIF('2026'!$B:$B, 'CONSOLIDADO AÑO 2026'!$A$3:$A$25) -> 5 | C25: =B25/$B$26 -> 0.0091407678
A26: TOTAL | B26: =SUM(B3:B25) -> 547 | C26: =B26/$B$26 -> 1

Sheet DETALLADO X MES 2026
A1: CUERPO DE BOMBEROS VOLUNTARIOS - LA UNIÓN VALLE | Z1: ="TOTAL DE EMERGENCIAS POR MES DE "&J2&" (2021-2025)" -> TOTAL DE EMERGENCIAS POR MES DE INCENDIO FORESTAL (2021-2025) | AA1: ="VARIACIÓN ANUAL DE "&J2&" (2021-2025)" -> VARIACIÓN ANUAL DE INCENDIO FORESTAL (2021-2025) | AB1: ="TOTAL DE "&J2&" POR AÑO (2021-2025)" -> TOTAL DE INCENDIO FORESTAL POR AÑO (2021-2025) | AC1: BUSCAR | AD1: CAÍDA / CORTES DE ARBOL | AE1: CONTROL DE ABEJAS | AF1: CONTROL DE AVISPAS | AG1: CAÍDA DE CUERDAS | AH1: CORTO CIRCUITO | AI1: COLAPSO DE ESTRUCTURAS | AJ1: CAPACITACIONES | AK1: EXTRICACIÓN VEHICULAR | AL1: FUGA DE GAS NATURAL | AM1: FUGA DE GAS GLP | AN1: INCENDIO FORESTAL | AO1: INCENDIO ESTRUCTURAL | AP1: INCENDIO VEHICULAR | AQ1: INUNDACIÓN | AR1: LABORES DE PREVENCION O ACOMPAÑAMIENTO EN GESTION DEL RIESGO | AS1: MATERIALES PELIGROSOS / DERRAMES | AT1: PRIMEROS AUXILIOS | AU1: RESCATE DE PERSONA / PARAPENTE | AV1: RESCATE DE ANIMAL | AW1: REUNIÓN EN LA ALCALDÍA | AX1: REUNIONES DE SERVICIO SOCIAL | AY1: SUMINISTROS DE AGUA | AZ1: VISITAS DE SEGURIDAD
A2: CONSOLIDAD ESTADÍSTICO DE: | J2: INCENDIO FORESTAL | Z2: ="TOTAL DE EMERGENCIAS POR MES DE "&A87&" HASTA ABRIL (2021-2026)" -> TOTAL DE EMERGENCIAS POR MES DE INCENDIO FORESTAL HASTA ABRIL (2021-2026) | AA2: ="VARIACIÓN ANUAL DE "&A87&" HASTA ENERO (2021-2026)" -> VARIACIÓN ANUAL DE INCENDIO FORESTAL HASTA ENERO (2021-2026) | AB2: ="TOTAL ANUAL DE "&A87&" HASTA ENERO (2021-2026)" -> TOTAL ANUAL DE INCENDIO FORESTAL HASTA ENERO (2021-2026)
A3: AÑO | B3: VARIACIÓN MENSUAL DEL TOTAL DE EMERGENCIAS POR AÑO | N3: TOTAL | O3: % INCIDENCIA | P3: PROM. X MES | Q3: PROM. X AÑO | R3: VARIACION % ANUAL
B4: ENERO | C4: FEBRERO | D4: MARZO | E4: ABRIL | F4: MAYO | G4: JUNIO | H4: JULIO | I4: AGOSTO | J4: SEPTIEMBRE | K4: OCTUBRE | L4: NOVIEMBRE | M4: DICIEMBRE
A5: 2021 | B5: =SUM('2021'!C4:C27) -> 4 | C5: =SUM('2021'!C29:C65) -> 4 | D5: =SUM('2021'!C67:C95) -> 0 | E5: =SUM('2021'!C97:C114) -> 0 | F5: =SUM('2021'!C116:C138) -> 1 | G5: =SUM('2021'!C140:C158) -> 1 | H5: =SUM('2021'!C160:C190) -> 2 | I5: =SUM('2021'!C192:C236) -> 0 | J5: =SUM('2021'!C238:C267) -> 0 | K5: =SUM('2021'!C269:C294) -> 0 | L5: =SUM('2021'!C296:C319) -> 0 | M5: =SUM('2021'!C321:C330) -> 0 | N5: =SUM(B5:M5) -> 12 | O5: =N5/$N$11 -> 0.065934066 | P5: =AVERAGE(B5:M5) -> 1 | Q5: =AVERAGE(N5:N9) -> 36.4 | R5: 0
A6: 2022 | B6: =SUM('2022'!C4:C22) -> 3 | C6: =SUM('2022'!C24:C54) -> 3 | D6: =SUM('2022'!C56:C87) -> 1 | E6: =SUM('2022'!C89:C128) -> 0 | F6: =SUM('2022'!C130:C167) -> 2 | G6: =SUM('2022'!C169:C210) -> 0 | H6: =SUM('2022'!C212:C270) -> 1 | I6: =SUM('2022'!C272:C324) -> 3 | J6: =SUM('2022'!C326:C364) -> 1 | K6: =SUM('2022'!C366:C408) -> 2 | L6: =SUM('2022'!C410:C452) -> 2 | M6: =SUM('2022'!C454:C484) -> 4 | N6: =SUM(B6:M6) -> 22 | O6: =N6/$N$11 -> 0.12087912 | P6: =AVERAGE(B6:M6) -> 1.8333333 | R6: =IF(N5=0,IF(N6=0,"0%","100%"),(N6-N5)/N5) -> 0.83333333
A7: 2023 | B7: =SUM('2023'!C4:C38) -> 6 | C7: =SUM('2023'!C40:C99) -> 4 | D7: =SUM('2023'!C101:C133) -> 1 | E7: =SUM('2023'!C135:C177) -> 1 | F7: =SUM('2023'!C179:C202) -> 1 | G7: =SUM('2023'!C204:C225) -> 6 | H7: =SUM('2023'!C227:C255) -> 8 | I7: =SUM('2023'!C257:C274) -> 8 | J7: =SUM('2023'!C285:C328) -> 14 | K7: =SUM('2023'!C330:C349) -> 1 | L7: =SUM('2023'!C351:C381) -> 3 | M7: =SUM('2023'!C383:C403) -> 9 | N7: =SUM(B7:M7) -> 62 | O7: =N7/$N$11 -> 0.34065934 | P7: =AVERAGE(B7:M7) -> 5.1666667 | R7: =IF(N6=0,IF(N7=0,"0%","100%"),(N7-N6)/N6) -> 1.8181818
A8: 2024 | B8: =SUM('2024'!C4:C12) -> 15 | C8: =SUM('2024'!C51:C105) -> 6 | D8: =SUM('2024'!C107:C166) -> 11 | E8: =SUM('2024'!C168:C207) -> 3 | F8: =SUM('2024'!C209:C212) -> 0 | G8: =SUM('2024'!C239:C263) -> 0 | H8: =SUM('2024'!C265:C290) -> 2 | I8: =SUM('2024'!C292:C324) -> 7 | J8: =SUM('2024'!C326:C342) -> 4 | K8: =SUM('2024'!C344:C370) -> 0 | L8: =SUM('2024'!C372:C390) -> 1 | M8: =SUM('2024'!C392:C412) -> 6 | N8: =SUM(B8:M8) -> 55 | O8: =N8/$N$11 -> 0.3021978 | P8: =AVERAGE(B8:M8) -> 4.5833333 | R8: =IF(N7=0,IF(N8=0,"0%","100%"),(N8-N7)/N7) -> -0.11290323
A9: 2025 | B9: =SUM('2025'!C4:C32) -> 7 | C9: =SUM('2025'!C34:C55) -> 0 | D9: =SUM('2025'!C57:C75) -> 1 | E9: =SUM('2025'!C77:C103) -> 2 | F9: =SUM('2025'!C105:C127) -> 1 | G9: =SUM('2025'!C129:C142) -> 0 | H9: =SUM('2025'!C144:C169) -> 5 | I9: =SUM('2025'!C171:C182) -> 6 | J9: =SUM('2025'!C184:C204) -> 5 | K9: =SUM('2025'!C206:C223) -> 1 | L9: =SUM('2025'!C225:C238) -> 0 | M9: =SUM('2025'!C240:C250) -> 3 | N9: =SUM(B9:M9) -> 31 | O9: =N9/$N$11 -> 0.17032967 | P9: =AVERAGE(B9:M9) -> 2.5833333 | R9: =IF(N8=0,IF(N9=0,"0%","100%"),(N9-N8)/N8) -> -0.43636364
A10: 2026 | B10: =SUM('2026'!C4:C18) -> 2 | C10: =SUM('2026'!C20:C53) -> 3 | D10: =SUM('2026'!C55:C78) -> 8 | E10: =SUM('2026'!C80:C101) -> 2 | F10: =SUM('2026'!C103:C127) -> 1 | G10: =SUM('2026'!C129:C151) -> 2 | H10: =SUM('2026'!C153:C171) -> 8 | I10: =SUM('2026'!C173:C527) -> 7
A11: GRAN TOTAL POR AÑOS | N11: =SUM(N5:N9) -> 182 | O11: =SUM(O5:O9) -> 1
A86: CUERPO DE BOMBEROS VOLUNTARIOS - LA UNIÓN VALLE ANÁLISIS COMPARATIVO DE EMERGENCIAS ACUMULADAS EN LO CORRIDO DEL AÑO FRENTE A AÑOS ANTERIORES
A87: =J2 -> INCENDIO FORESTAL
A88: AÑO | B88: ENERO | C88: FEBRERO | D88: MARZO | E88: ABRIL | F88: MAYO | G88: JUNIO | H88: JULIO | I88: AGOSTO | J88: SEPTIEMBRE | K88: OCTUBRE | L88: NOVIEMBRE | M88: DICIEMBRE | N88: TOTAL | O88: % INCIDENCIA | P88: PROM. X MES | Q88: PROM. X AÑO | R88: VARIACION % ANUAL
A89: 2021 | B89: =B5 -> 4 | C89: =C5 -> 4 | D89: =D5 -> 0 | E89: =E5 -> 0 | F89: =F5 -> 1 | G89: =G5 -> 1 | H89: =H5 -> 2 | I89: =I5 -> 0 | N89: =SUM(B89:M89) -> 12 | O89: =N89/$N$95 -> 0.075471698 | P89: =AVERAGE(B89:M89) -> 1.5 | Q89: =AVERAGE(N89:N94) -> 26.5 | R89: 0
A90: 2022 | B90: =B6 -> 3 | C90: =C6 -> 3 | D90: =D6 -> 1 | E90: =E6 -> 0 | F90: =F6 -> 2 | G90: =G6 -> 0 | H90: =H6 -> 1 | I90: =I6 -> 3 | N90: =SUM(B90:M90) -> 13 | O90: =N90/$N$95 -> 0.081761006 | P90: =AVERAGE(B90:M90) -> 1.625 | R90: =IF(N89=0,IF(N90=0,"0%","100%"),(N90-N89)/N89) -> 0.083333333
A91: 2023 | B91: =B7 -> 6 | C91: =C7 -> 4 | D91: =D7 -> 1 | E91: =E7 -> 1 | F91: =F7 -> 1 | G91: =G7 -> 6 | H91: =H7 -> 8 | I91: =I7 -> 8 | N91: =SUM(B91:M91) -> 35 | O91: =N91/$N$95 -> 0.22012579 | P91: =AVERAGE(B91:M91) -> 4.375 | R91: =IF(N90=0,IF(N91=0,"0%","100%"),(N91-N90)/N90) -> 1.6923077
A92: 2024 | B92: =B8 -> 15 | C92: =C8 -> 6 | D92: =D8 -> 11 | E92: =E8 -> 3 | F92: =F8 -> 0 | G92: =G8 -> 0 | H92: =H8 -> 2 | I92: =I8 -> 7 | N92: =SUM(B92:M92) -> 44 | O92: =N92/$N$95 -> 0.27672956 | P92: =AVERAGE(B92:M92) -> 5.5 | R92: =IF(N91=0,IF(N92=0,"0%","100%"),(N92-N91)/N91) -> 0.25714286
A93: 2025 | B93: =B9 -> 7 | C93: =C9 -> 0 | D93: =D9 -> 1 | E93: =E9 -> 2 | F93: =F9 -> 1 | G93: =G9 -> 0 | H93: =H9 -> 5 | I93: =I9 -> 6 | N93: =SUM(B93:M93) -> 22 | O93: =N93/$N$95 -> 0.13836478 | P93: =AVERAGE(B93:M93) -> 2.75 | R93: =IF(N92=0,IF(N93=0,"0%","100%"),(N93-N92)/N92) -> -0.5
A94: 2026 | B94: =B10 -> 2 | C94: =C10 -> 3 | D94: =D10 -> 8 | E94: =E10 -> 2 | F94: =F10 -> 1 | G94: =G10 -> 2 | H94: =H10 -> 8 | I94: =I10 -> 7 | N94: =SUM(B94:M94) -> 33 | O94: =N94/$N$95 -> 0.20754717 | P94: =AVERAGE(B94:M94) -> 4.125 | R94: =IF(N93=0,IF(N94=0,"0%","100%"),(N94-N93)/N93) -> 0.5
A95: GRAN TOTAL POR AÑOS | N95: =SUM(N89:N94) -> 159 | O95: =SUM(O89:O94) -> 1

Sheet 2026
A1: TIPO DE INCIDENTE | B1: INCIDENTES Y ACTIVIDADES | C1: CANTIDAD DE | D1: DÍA DEL EVENTO | E1: DURACIÓN DEL EVENTO | F1: DIRECCIÓN O LUGAR DE REFERENCIA | G1: BARRIO CORREGIMIENTO O VEREDA | H1: DESCRIPCIÓN DEL EVENTO | I1: AREA AFECTADA (SOLO SI APLICA) | J1: N° DE UNIDADES QUE ASISTIERON | K1: VEHÍCULO | L1: COORDENADAS
C2: ='DETALLADO X MES 2026'!J2 -> INCENDIO FORESTAL
A3: ENERO
A4: INCENDIOS | B4: INCENDIO FORESTAL | C4: =COUNTIF(B4:B18,C2) -> 2 | D4: 46024 | E4: 1 HORA Y MEDIA | F4: VIA LAS CINTAS | H4: INFORMAN DE HUMO EN LA MONTAÑA | I4: 200 MTR | J4: 9 | K4: B-4, L-1, L-2
A5: OTROS | B5: CAÍDA / CORTES DE ARBOL | D5: 46028 | E5: 4.10 HORAS | F5: LA BASCULA DE CERVALLE | G5: CORCEGA | H5: ARBOL QUE CAE TAPONANDO PARTE DE LA VIA Y AFECTANDO UNA VIVIENDA | I5: 100 M/2 | J5: 3 | K5: L-1
A6: OTROS | B6: CONTROL DE AVISPAS | D6: 46029 | E6: 1 HORA | F6: CALLE 20 CRA 17 | G6: LA CRUZ | H6: RECUPERACION Y LIBERACION DE ENJAMBRE DE AVISPAS QUE ESTAN DENTRO DE UNA VIVIENDA | I6: 10 MT/2 | J6: 3 | K6: L-2
A7: INCENDIOS | B7: INCENDIO ESTRUCTURAL | D7: 46030 | E7: 12 MNTOS | F7: CALLE 13 CRA 8 | G7: LAS LAJAS | H7: POSIBLE INCENDIO ESTRUCTURAL,RESULTANDO SER UN SARTEN QUE SE ESTABA QUEMANDO | I7: 10 MT/2 | J7: 3 | K7: B-4
A8: RESCATES | B8: RESCATE DE PERSONA / PARAPENTE | D8: 46035 | E8: 1 HORA | F8: MANZANA B CASA 6 | G8: LA ANDINA | H8: INFORMAN DE UN MENOR ATRAPADO EN UN BAÑO, POR UN CAJON QUE CAE Y BLOQUEA LA PUERTA | I8: . | J8: 4 | K8: B-3
A9: INCENDIOS | B9: INCENDIO ESTRUCTURAL | D9: 46038 | E9: 2 HORAS | F9: CARRERA 15 CON CALLE 15 | G9: CENTRO | H9: INCENDIO EN UN LOCAL DEL CENTRO | I9: . | J9: 8 | K9: B-2, B-4
A10: RESCATES | B10: RESCATE DE PERSONA / PARAPENTE | D10: 46042 | E10: 2 HORAS | F10: ZONA DEL AJISAL | G10: EL AJISAL | H10: RESCATE DE PILOTO DE PARAPENTE QUE CAE EN LA ZONA ALTA DEL AJISAL, PILOTO SALE POR SUS PROPIOS MEDIOS | I10: * | J10: 8 | K10: L-1, L-2
A11: FALSA ALARMA | B11: INCENDIO FORESTAL | D11: 46043 | E11: 27 MNTOS | F11: VIA LAS CINTAS | G11: LAS CINTAS | H11: QUEMA VEGETAL CONTROLADA | I11: * | J11: 6 | K11: B-2, L-2
A12: RESCATES | B12: RESCATE DE PERSONA / PARAPENTE | D12: 23/12/0026 | E12: 2.30 HORAS | F12: CERRO DE SANTA ELENA | G12: SANTA ELENA | H12: PILOTOS DE PARAPENTES QUE SE ENREDAN EN VUELO Y SUFREN CAIDA SALIENDO ILESOS | I12: * | J12: 10 | K12: B-3, L-2
A13: OTROS | B13: CONTROL DE ABEJAS | D13: 23/12/0026 | E13: 40 MNTOS | F13: VIA A SAN LUIS | G13: SAN LUIS | H13: NO SE ENCONTRO LA DIRECCION | I13: * | J13: 2 | K13: L-2
A14: MATERIALES PELIGROSOS | B14: FUGA DE GAS NATURAL | D14: 46048 | E14: 54 MNTOS | F14: CRA 15 #7a 36 | G14: LA CIUDADELA BAJA | H14: FUERTE OLOR A GAS ,SIN ENCONTRAR CAUSAS | I14: 45MT/2 | J14: 2 | K14: L-1
A15: INCENDIOS | B15: INCENDIO ESTRUCTURAL | D15: 46050 | E15: 2.33 HORAS | F15: TRANS 17 CRA 17 | G15: SAN PEDRO | H15: INCENDIO ESTRUCTURAL EN VIVIENDA UTILIADA PARA ALMACENAR PRODUCTOS DE RECICLAJE | I15: * | J15: 11 | K15: B-2, B-4, L-2, OTROS
A16: MATERIALES PELIGROSOS | B16: FUGA DE GAS NATURAL | D16: 46050 | E16: 43 MNTOS | F16: CRA 18 #14 19 | G16: popular | H16: FUGA DE GAS EN VIVIENDA | I16: * | J16: 6 | K16: B-4
A17: RESCATES | B17: RESCATE DE ANIMAL | D17: 46052 | E17: 1 HORA | F17: CALLE 8 # 9 - 120 | G17: LAS PALMAS | H17: GATO QUE QUEDA ATRAPADO EN UN TECHO | I17: . | J17: 4 | K17: B-3
A18: RESCATES | B18: RESCATE DE PERSONA / PARAPENTE | D18: 46052 | E18: 2 HORAS | F18: VOLADERO DE LA AGUADA | G18: LA AGUADA | H18: PILOTO DE PARAPENTE QUE CAE EN EL SECTOR DEL VOLADERO DE LA AGUADA,SE REQUIERE TRASLADO EN AMBULANCIA | I18: * | J18: 5 | K18: L-2
A19: FEBRERO
A20: OTROS | B20: CONTROL DE ABEJAS | C20: =COUNTIF(B20:B53,C2) -> 3 | D20: 46056 | E20: 30 MINUTOS | F20: COLEGIO ITDG | G20: EL AMPARO | H20: ABEJAS AL PARECER PASAGERAS | I20: N/A | J20: 2 | K20: L-2
A21: MATERIALES PELIGROSOS | B21: FUGA DE GAS GLP | D21: 46056 | E21: 30 MINUTOS | F21: CR 15 7A-36 | G21: LA CIUDADELA | H21: CILINDRO DE GAS QUE PRESENTA FUGA, SE TRAJO PARA LA PARTE DE LA ESCUELA | I21: N/A | J21: 1 | K21: L-2
A22: RESCATES | B22: RESCATE DE ANIMAL | D22: 46057 | E22: 1 HORA 30 MINUTOS | F22: TRASVERSAL 17 | H22: RESCATE DE UN FELINO EN UN ALJIBER | I22: N/A | J22: 6 | K22: B-3
A23: INCENDIOS | B23: INCENDIO FORESTAL | D23: 46055 | E23: 40 MNTOS | F23: CRA 16 #25 04 | G23: LA CAMPESINA | H23: QUEMA DE RESIDUOS SOLIDOPS QUE ESTAN REALIZANDO DOS ADULTOS MAYORES. SE REALIZA SOFOCACION | I23: 10 MT/2 | J23: 2 | K23: B-4
A24: INCENDIOS | B24: INCENDIO FORESTAL | D24: 46058 | E24: 45 MNTOS | F24: LA CAMPESINA ALTA | G24: LA CAMPESINA | H24: POSIBLE QUEMA DE DESECHOS SIENDO FALSA ALARMA | I24: * | J24: 6 | K24: B-4, L-2
A25: INSPECCIONES DE SEGURIDAD | B25: VISITAS DE SEGURIDAD | D25: 46059 | E25: 3 HORAS | F25: BAR LOS AMIGOS, EL REY DEL DESPECHO Y FINCA VILLA LIANA | G25: LA UNION | H25: SE REALIZAN VISITA PARA DAR CONCEPTO DE SEGURIDAD | I25: . | J25: 1 | K25: L-1
A26: MATERIALES PELIGROSOS | B26: MATERIALES PELIGROSOS / DERRAMES | D26: 46062 | E26: 2 HORAS | F26: CARRERA 15 CON CALLE 12 | G26: BELEN | H26: INFORMAN DE UN BULTO QUE CAE DE UNA MOTO, CON UN PRODUCTO AGRICOLA TOXICO | I26: . | J26: 5 | K26: B-4, L-2
A27: OTROS | B27: CAÍDA / CORTES DE ARBOL | D27: 46062 | E27: 45 MNTOS | F27: VIA PANORAMA KM1 EL AMPARO SAN LUIS | G27: MARTINDOZA | H27: ARBOL QUE CAE TAPONANDO EL CARRIL EN SENTIDO EL AMPARO SAN LUIS | I27: 100 MT/2 | J27: 7 | K27: B-3
A28: MATERIALES PELIGROSOS | B28: FUGA DE GAS NATURAL | D28: 46063 | E28: 30 MINUTOS | F28: PAJARO DE ORO | G28: PAJARO DE ORO | H28: FUGA DE GAS NATURAL | I28: N/A | J28: 5 | K28: B-2, L-2
A29: MATERIALES PELIGROSOS | B29: FUGA DE GAS NATURAL | D29: 46065 | E29: 1 HORA | F29: CALLE 17 # 14 - 57 | G29: EL POPULAR | H29: INFORMAN DE UNA FUGA DE GAS DURANTE TRABAJO EN LA VIA | I29: . | J29: 5 | K29: B-4, L-2
A30: MATERIALES PELIGROSOS | B30: FUGA DE GAS NATURAL | D30: 46066 | E30: 30 MINUTOS | F30: CRA 15 CON CL 17 | H30: FUGA DE GAS POR ROMPIMIENTO DEL TUBO QUE LO TRANSPORTA | I30: N/A | J30: 7 | K30: B-2, L-2
A31: INCENDIOS | B31: INCENDIO FORESTAL | D31: 46065 | E31: 4.40 HORAS | F31: MORELIA | G31: SANTA RITA | H31: APOYO OPERATIVO CON MAQUINAA EXTINTORA,CARROTANQUE Y PERSONAL, AL CBV DE ROLDANILLO EN QUEMA DE RESIDUOS AGRICOLAS,QUE SE SALEN DE CONTROL | I31: 2 HECTAREAS | J31: 11 | K31: B-4, L-1, OTROS
A32: INCENDIOS | B32: CORTO CIRCUITO | D32: 46068 | E32: 1 HORA | F32: VIA SAN LUIS S/N 730 | G32: SAN LUIS | H32: INFORMAN DE UN POSTE EN LLAMAS | I32: . | J32: 3 | K32: B-4
A33: MATERIALES PELIGROSOS | B33: FUGA DE GAS NATURAL | D33: 46070 | E33: 47 MNTOS | F33: CALLE 21 CRA 15 ESQU | G33: SAN PEDRO | H33: FUGA DE GAS NATURAL POR ROMPIMIENTO EN LA TUBERIA AL REALIZAR TRABAJOS DE CONSTRUCCION | I33: 100MT/2 | J33: 5 | K33: B-2, L-2
A34: RESCATES | B34: RESCATE DE ANIMAL | D34: 46071 | E34: 1 HORA | F34: CARRERA 10 # 15 - 28 | G34: BELEN | H34: INFORMAN DE UN GATO EN UN ARBOL QUE SE DIFICULTA BAJAR POR MOTIVOS DE LLUVIA | I34: . | J34: 3 | K34: B-2
A35: OTROS | B35: CAÍDA / CORTES DE ARBOL | D35: 46074 | E35: 2 HORAS | F35: CRA 12 CALLE10 | G35: BELEN | H35: POR FUERTES VIENTO EN EL MNPIO SE CAE UN ARBOL SOBRE LA PARTE SUPERIOR DE UNA VIVIENDA, RESULTANDO AFECTADO EL TECHO | I35: 40 M/2 | J35: 5 | K35: L-2
A36: OTROS | B36: COLAPSO DE ESTRUCTURAS | D36: 46074 | E36: 1 HORA | F36: EL JORDAN | G36: EL JORDAN | H36: TECHO DE GUADUA Y ZINC QUE POR LOS FUERTE VIENTOS EN EL MPIO SE CAE A LA VIA PUBLICA | I36: 40 MT/2 | J36: 5 | K36: L-2
A37: RESCATES | B37: CONTROL DE ABEJAS | D37: 46073 | E37: 1.05 HORAS | F37: CALLE 11 CRA 15 ESQ | G37: CALLE LINDA | H37: VERIFICACION DE ABEJAS EN VIVIENDA | I37: * | J37: 1 | K37: L-1
A38: RESCATES | B38: CONTROL DE ABEJAS | D38: 46073 | E38: 20 MNTOS | F38: CASA CONSISTORIAL | G38: ZONA CENTRO | H38: APOYO A PERSONAL DE LA ALCALDIA EN RECUPERACION DE ABEJAS | I38: 30 MT/2 | J38: 2 | K38: L-1
A39: RESCATES | B39: CONTROL DE ABEJAS | D39: 46074 | E39: 40 MNTOS | F39: CASA CONSISTORIAL | G39: ZONA CENTRO | H39: APOYO OPERATIVO AL PERSONAL DE HUMATA PARA CAPTURAR ABEJAS QUE ESTAN EN EL TECHO DE LA CASA CONSISTORIAL | I39: 50 MT/2 | J39: 5 | K39: L-2
A40: OTROS | B40: CAÍDA / CORTES DE ARBOL | D40: 46076 | E40: 1.05 HORAS | F40: CRA 27 23 125 | G40: EL CARMEN | H40: ARBOL QUE CAE POR FUERTES AGUACEROS EN LA MADRUGA , TAPOBNANDO LA VIA ENTRE SAN JOSE Y EL AJISAL DEJANDO HABITANTES SIN PASO VEHICULAR | I40: 50MT/2 | J40: 4 | K40: L-1
...

Sheet 2025
A1: TIPO DE INCIDENTE | B1: INCIDENTES Y ACTIVIDADES | C1: CANTIDAD DE | D1: DÍA DEL EVENTO | E1: DURACIÓN DEL EVENTO | F1: DIRECCIÓN O LUGAR DE REFERENCIA | G1: BARRIO CORREGIMIENTO O VEREDA | H1: DESCRIPCIÓN DEL EVENTO | I1: AREA AFECTADA (SOLO SI APLICA) | J1: N° DE UNIDADES QUE ASISTIERON | K1: VEHÍCULO
C2: ='DETALLADO X MES 2026'!J2 -> INCENDIO FORESTAL
A3: ENERO
A4: OTROS | B4: FUGA DE GAS NATURAL | C4: =COUNTIF(B4:B32,C2) -> 7 | D4: 45666 | E4: 1 HORA | F4: CALLE 23A 12 68 | G4: SAN PEDRO | H4: RUPTURA DE TUBERIA DE GAS DURANTE TRABAJO EN VIVIENDA | I4: . | J4: 4
A5: INSPECCIONES DE SEGURIDAD | B5: VISITAS DE SEGURIDAD | D5: 45670 | E5: 1 HORA | F5: CALLE 15 CRA 15 ESQ | G5: ZONA CENTRO | H5: VISITA DE SEGURIDAD A BANCO DE OCCIDENTE | I5: * | J5: 1
A6: INSPECCIONES DE SEGURIDAD | B6: VISITAS DE SEGURIDAD | D6: 45670 | E6: 1 HORA | F6: CRA 14 CALLE 12 | G6: ZONA CENTRO | H6: VISITA DE SEGURIDAD A LOCAL DIVINAS BELLEZA INTEGRAL | I6: * | J6: 1
A7: INSPECCIONES DE SEGURIDAD | B7: LABORES DE PREVENCION O ACOMPAÑAMIENTO EN GESTION DEL RIESGO | D7: 45671 | E7: 1.10 HORAS | F7: CAPILLA DE LA ERMITA | G7: BELEN | H7: SE REALIZA INSPECCION OCULAR A LA CAPILLA DE LA ERMITA, DEBIDO A SU DETERIORO EN EL TECHO | I7: * | J7: 2
A8: OTROS | B8: RESCATE DE ANIMAL | D8: 45672 | E8: 1 HORA | F8: FINCA LOS LIMONES | G8: VEREDA EL GUASIMO | H8: SE REALIZA CONTROL DE UN ENJAMBRE DE AVISPAS | I8: . | J8: 3
A9: FALSA ALARMA | B9: INCENDIO FORESTAL | D9: 45674 | E9: 28 MINUTOS | F9: ALREDEDORES BARRIO EL AMPARO | G9: EL AMPARO | H9: REPORTE DE UN INCENDIO FORESTAL QUE RESULTÓ EN FALSA ALARMA YA QUE SE TRATABA DE UNA QUEMA CONTROLADA DENTRO DE LOS PREDIOS DE UNA EMPRESA PRIVADA | I9: NA | J9: 5
A10: RESCATES | B10: RESCATE DE ANIMAL | D10: 45675 | E10: 37 MNTOS | F10: CALLE 22 CRA 18 | G10: SAN PEDRO | H10: RESCATE ANIMAL DE UNA SARIGUEYA LA CUAL NO SE ENCONTRO EN LA VIVIENDA | I10: * | J10: 2
A11: INCENDIOS | B11: INCENDIO FORESTAL | D11: 45676 | E11: 3.37 HORAS | F11: APOYO OPERATIVO AL CBV LA VICTORIA | G11: LA VICTORIA | H11: APOYO OPERATIVO EN INCENDIO AGRICOLA AL CBV DE LA VICTORIA | I11: * | J11: 4
A12: INCENDIOS | B12: INCENDIO VEHICULAR | D12: 46011 | E12: 1.33 HORAS | F12: HACIENDA EL CORTIJO | G12: CORCEGA | H12: SE RECIBE LLAMADO DE LA SÑRA LEYDI INFORMANDO DE UNA QUEMA DE CAÑA,AL LLEGAR AL SITIO ES UN INCENDIO VEHICULAR AGRICOLA | I12: * | J12: 10
A13: OTROS | B13: FUGA DE GAS NATURAL | D13: 45678 | E13: 35 MNTOS | F13: CRA 19 #19 40 | G13: SAN PEDRO ARRIBA | H13: FUGA DE GAS NATURAL POR ROMPIMIENTO DE TUBERIA | I13: * | J13: 4
A14: INSPECCIONES DE SEGURIDAD | B14: VISITAS DE SEGURIDAD | D14: 45679 | E14: 1.30HORAS | F14: BANCO DE LA MUJER | G14: ZONA CENTRO | H14: VISITA DE SEGURIDAD A ENTIDA BANCARIA | I14: * | J14: 1
A15: INCENDIOS | B15: INCENDIO FORESTAL | D15: 45680 | E15: 39 MNTOS | F15: LINDEROS | G15: LINDEROS | H15: QUEMA DE RASTROJO POR LA TERCERA CANAL | I15: 100 MT | J15: 5
A16: BUSQUEDA Y RESCATE | B16: RESCATE DE PERSONA / PARAPENTE | D16: 45681 | E16: 2.30 HORAS | F16: LA BALASTRERA VIA QUEBREDA GRANDE | G16: LA BALASTRERA | H16: APOYO OPERATIVO A PONAL EN LA BUSQUEDAD DE PERSONA DESAPARECIDA EN LA ZONA MONTAÑOSA DE LA UNION | I16: * | J16: 4
... A19: RESCATES | B19: RESCATE DE ANIMAL | D19: 45681 | E19: 2.12 HORAS | F19: CRA 25 12 73 | G19: VIA CASA BLANCA | H19: SE REALIZA EL RESCATE DELOS GATOS ,EL DIA ANTERIOR NO FUE POSIBLE REALIZAR EL RESCATE,POR QUE NO SE ENCONTRARON LOS ANIMALITOS | I19: * | J19: 2
A20: INCENDIOS | B20: INCENDIO FORESTAL | D20: 45682 | E20: 2 HORAS | F20: LA VICTORIA | H20: APOYO A LA VICTORIA VALLE DEL CAUCA EN INCENDIO FORESTAL | I20: N/A | J20: 4
A21: BUSQUEDA Y RESCATE | B21: RESCATE DE PERSONA / PARAPENTE | D21: 45682 | E21: 1.34 HORAS | F21: LA BALASTRERA | G21: LA BALASTRERA VIA QUEBRADA GRANDE | H21: SE PRESTA APOYO PARA RECUPERACION DE CADAVER Y MOTOCICLETA DE PERSONA QUE ESTABA DESAPARECIDA | I21: * | J21: 5
A22: INCENDIOS | B22: INCENDIO FORESTAL | D22: 45683 | E22: 4.10 HORAS | F22: LA VICTORIA VALLE | G22: LA VICTORIA | H22: APOYO OPERATIVO EN INCENDIO AGRICOLA AL CBV DE LOA VICTORIA | I22: * | J22: 4
A23: INCENDIOS | B23: INCENDIO ESTRUCTURAL | D23: 45684 | E23: 3.10 HORAS | F23: VEREDA EL RINCON | G23: VEREDA EL RINCON | H23: INCENDIO ESTRUCTURAL CON PERDIDA TOTAL DE VIVIENDA,ENCERES,MOTOCICLETA Y ANIMALES DOMESTICOS | I23: * | J23: 13
A24: OTROS | B24: CONTROL DE ABEJAS | D24: 45685 | E24: 1 HORA | F24: CALLE 18B 12 21 | G24: EL POPULAR | H24: UN ENJAMBRE DE ABEJAS EN EL TECHO DE UN TERCER PISO | I24: . | J24: 5
A25: OTROS | B25: SUMINISTROS DE AGUA | D25: 45685 | E25: 3 HORAS | F25: ZONAS VERDES DEL MUNICIPIO | G25: SAN LUIS - BELEN | H25: SE PRESTA SERVICIO DE RIEGO EN ALGUNOS LUGAR CON ZONA VERDE EN EL MUNICIPIO | I25: . | J25: 4
A26: RESCATES | B26: RESCATE DE PERSONA / PARAPENTE | D26: 45686 | E26: 1 HORA | F26: EL LUCERO | G26: EL LUCERO | H26: PARAPENTE QUE ATERRISO AL PARECER CON DIFICULTAD | I26: N/A | J26: 9
A27: INCENDIOS | B27: INCENDIO FORESTAL | D27: 45686 | E27: 30 MINUTOS | F27: CR 8 CLL 14 | G27: BELEN | H27: INFORMA LA COMUNIDAD QUE UNA PERSONA QUEMA UNA BASURA QUE SE ENCONTRABA EN UN LOTE Y SE SALE DE CONTROL | I27: . | J27: 4
A28: OTROS | B28: PRIMEROS AUXILIOS | D28: 45686 | E28: 1 HORA | F28: VIA LA UNION - SAN LUIS | G28: PRADOS DEL NORTE | H28: SE PRESTA PRIMEROS AUXILIOS A UNA PERSONA TRAS COLISION DE DOS MOTOCICLISTAS | I28: . | J28: 4
A29: INSPECCIONES DE SEGURIDAD | B29: VISITAS DE SEGURIDAD | D29: 45687 | E29: 23 MNTOS | F29: CALLE 14 3 172 | G29: LAS LAJAS | H29: SE REALIZA INSPECCION DE SEGURIDAD A ESTABLECIMIENTO LOKATEL COCTELES | I29: * | J29: 1
A30: INSPECCIONES DE SEGURIDAD | B30: VISITAS DE SEGURIDAD | D30: 45687 | E30: TREINTE MINUTOS | F30: CALL 14 # 3 172 | G30: LAS LAJAS | H30: INSPECION DE SEGURIDAD | I30: N/P | J30: 1
A31: INCENDIOS | B31: INCENDIO FORESTAL | D31: 45688 | E31: UNA HORA | F31: KR 15 EL LUCERO | G31: BARRIO EL LUCERO PISTA DE MOTOS | H31: INCENDIO DE SINGLA | I31: N/P | J31: 4
A32: OTROS | B32: CONTROL DE ABEJAS | D32: 45688 | E32: 1.15 HORAS | F32: IGLESIA DE LA ERMITA | G32: LAS LAJAS | H32: CONTROL Y RECUPERACION DE ABEJAS E | I32: * | J32: 2
A33: FEBRERO
A34: MATERIALES PELIGROSOS | B34: MATERIALES PELIGROSOS / DERRAMES | C34: =COUNTIF(B34:B55,C2) -> 0 | D34: 45689 | E34: 1.26 HORAS | F34: CRA 18 Y 19 CALLE 16 HASTA | G34: SECTOR DE LA GALERIA | H34: DERRAME DE ACEITE DE MOTOR APROXIMADAMENTE 160 MT | I34: 160 MT LINEALES | J34: 6 | K34: B-2, B-3
A35: RESCATES | B35: RESCATE DE PERSONA / PARAPENTE | D35: 45690 | E35: CUATRO HORAS | F35: VEREDA EL LUCERO | G35: EL LUCERO | H35: SE REALIZA EL RESCATE DE UN PARAPENTE QUE CAE EN ZONA BOSCOSA DE LA VEREDA EL LUCERO, SIENDO ENCONTRADO SIN LECIONES Y MOVILIZÁNDOSE POR SUS PROPIOS MEDIOS. SE HACE LA EXTRACIÓN DEL ÁREA Y SE DEJA EN LA TERMINAL DE TRANSPORTES YA QUE SU ALOJAMIENTO SE UBICA EN ROLDANILLO. | I35: NA | J35: 8 | K35: B-3, L-1
A36: OTROS | B36: PRIMEROS AUXILIOS | D36: 45692 | E36: 49 MNTOS | F36: VEREDA EL RINCON | G36: VEREDA EL RINCON | H36: PERSONA QUE RESULTA AFECTEDA EN DEDO DE LA MANO IZQUIERDA EN LABORES DEL CAMPO,FUE TRASLADADA AL HOSPITAL LOCAL | I36: * | J36: 2 | K36: L-1
A37: OTROS | B37: INUNDACIÓN | D37: 45693 | E37: 26 MNTO | F37: PUENTE DE LOS MIRANDAS | G37: LAS LAJAS | H37: VIVIENDA QUE RESULTA INUNDADA POR COLAPSO DE AGUAS LLUVIAS EN LA VIA, SIN INTERVENSION | I37: 40 MT | J37: 5 | K37: B-3
A38: OTROS | B38: INUNDACIÓN | D38: 45693 | E38: 25 MNTOS | F38: CRA 11 CALLE 8 ESQUINA | G38: BELEN | H38: VIVIENDAS QUE RESULTAN AFECTADAS POR AGUAS LLUVIAS, DEVIDO AL TAPONAMIENTO DEL SERVICIO DE ALCANTARILLADO, SIN INTERVENSION DE LAS UNIDADES | I38: 80 MT | J38: 5 | K38: B-3
A39: INCENDIOS | B39: CORTO CIRCUITO | D39: 45694 | E39: 35 MNTOS | F39: CALLE 18 CRA 13 | G39: PORTAL DE LA ANDINA | H39: INCENDIO ELECTRICO EN TRANSFORMADOR | I39: * | J39: 2 | K39: B-2
A40: MATERIALES PELIGROSOS | B40: FUGA DE GAS GLP | D40: 45694 | E40: 3.25 HORAS | F40: VIA PANORAMA KL 1 VIA R/NILLO HOTEL LOS VIÑEDOS | G40: EL PORTACHUELO | H40: FUGA DE GLP POR AVERIA DE VALVULA DE ALIVIO | I40: 100 MT | J40: 9 | K40: B-3, B-4
A41: MATERIALES PELIGROSOS | B41: FUGA DE GAS GLP | D41: 45694 | E41: 3.15 HORAS | F41: HOTEL LOS VIÑEDOS | G41: EL PORTACHUELO | H41: FUGA DE GAS POR ROMPIMIENTO DE TAPON, QUE SE HABIA INSTALADO EN LA PRIMER EMERGENCIA EN EL MISMO CONTENEDOR | I41: 100 MT | J41: 5 | K41: B-2, OTROS
A42: MATERIALES PELIGROSOS | B42: FUGA DE GAS NATURAL | D42: 45696 | E42: 1.07 HORAS | F42: CALLE 23 # 12 83 | G42: SAN PEDRO | H42: FUGA DE GAS NATURAL POR ROMPIMIENTO DE TUBERIA | I42: 50 MT | J42: 4 | K42: B-2
...

Sheet 2024
A1: TIPO DE INCIDENTE | B1: INCIDENTES Y ACTIVIDADES | C1: CANTIDAD DE | D1: DÍA DEL EVENTO | E1: DURACIÓN DEL EVENTO | F1: DIRECCIÓN O LUGAR DE REFERENCIA | G1: BARRIO CORREGIMIENTO O VEREDA | H1: DESCRIPCIÓN DEL EVENTO | I1: AREA AFECTADA (SOLO SI APLICA) | J1: N° DE UNIDADES QUE ASISTIERON | K1: VEHÍCULO | L1: COORDENADAS
C2: ='DETALLADO X MES 2026'!J2 -> INCENDIO FORESTAL
A3: ENERO
A4: OTROS | B4: FUGA DE GAS NATURAL | C4: =COUNTIF(B4:B49,$C$2) -> 15 | D4: 45295 | E4: UNA HORA Y TREINTA MINUTOS | F4: CAMPESINA PARTE BAJA | G4: LA CAMPESINA | H4: FUGA DE GAS POR RUTURA EN ESCABACION | I4: NO APLICA | J4: 3 | K4: B-4
A5: OTROS | B5: CONTROL DE ABEJAS | D5: 45295 | E5: UNA HORA | F5: CARRERA 15 CON CALLE | G5: CENTRO | H5: SE REALIZA RERCUPERACION DE ABEJAS EN EL ANDEN DEL BANCO DE DAVIVIENDA SON LIBERADAS POR LA BALASTRERA LLENDO PARA VERSALLES | I5: 0 | J5: 2 | K5: L-2
A6: FALSA ALARMA | B6: RESCATE DE PERSONA / PARAPENTE | D6: 45295 | E6: DOS HORAS | F6: VIA LA UNION LA VICTORIA | G6: LA ISLA | H6: INFORMAN DE UN PARAPENTE QUE PIERDE CONTROL SE PRESIPITA AL SUELO SE BUSCOO POR LOS LADOS DE LA SEGUNDA CANAL NO ENCONTRARON NADA | I6: 0 | J6: 3 | K6: L-2
A7: INCENDIOS | B7: INCENDIO FORESTAL | D7: 45296 | E7: CUARENTA MINUTOS | F7: CALLE 24 13 38 | G7: SAN PEDRO | H7: SE REALIZA LIQUIDACION DEL FUEGO A UN CONTROL DE QUE CONTROLADA QUE ESTABA AFETANDO LOS VECINOS CON EL HUMO | I7: 100 METROS CUADRADOS | J7: 3 | K7: B-4
A8: INCENDIOS | B8: INCENDIO FORESTAL | D8: 45297 | E8: MEDIA HORA | F8: PEDREGAL | G8: EL ESPINAL | H8: AL LLEGAR AL SITIO ES UNA QUEMA CONTROLADA A LA ORRILLA DE LA CANAL POR UN TRABAJOR DE LA FINCA | I8: 100 MTROS LINEALES | J8: 6 | K8: B-4, L-2
A9: INCENDIOS | B9: INCENDIO VEHICULAR | D9: 45296 | E9: TREINTA MINUTOS | F9: VIA LA UNION LA VICTORIA | G9: VIA LA UNION LA VICTORIA | H9: MOTOCICLETA INCENDIADA | I9: NO APLICA | J9: 4 | K9: B-4
A10: INCENDIOS | B10: INCENDIO FORESTAL | D10: 45299 | E10: VEINTE MINUTOS | F10: PARTE TRACERA EMPRESA GRAJALES | G10: LAS CINTAS | H10: QUEMA CONTROLADA | I10: NO APLICA | J10: 3 | K10: B-4
A11: INCENDIOS | B11: INCENDIO ESTRUCTURAL | D11: 45300 | E11: 0.052083333 | F11: CALLE 16 # 2-55 | G11: LAS LAJAS | H11: INCENDO COSINA FOGON DE LEÑA DEL RESTAURANTE EL SANCOCHASO | I11: N/A | J11: 8 | K11: B-4, L-2, L-3
A12: INCENDIOS | B12: INCENDIO FORESTAL | D12: 45300 | E12: TRES HORAS CON VEINTE MINUTOS | F12: MIRADOR DE LAS BRISAS | G12: MIRADOR DE LAS BRISAS | H12: MIRADOR DE LA BRISAS | I12: NO APLICA | J12: 7 | K12: B-1, B-4, L-2
A13: INCENDIOS | B13: INCENDIO FORESTAL | D13: 45300 | E13: TRES HORAS Y MEDIA | F13: FRENTE A LA URB LAS BRISAS | G13: LAS BRISAS | H13: SE REALIZA CONTROL DE INCENDIO DE MADERA DESTROZADA QUE HABIAN AMONTONADO DESE VARIOS DIAS ATRAS | I13: UNA PLAZA | J13: 12 | K13: B-1, B-3, B-4, L-2
A14: OTROS | B14: CONTROL DE ABEJAS | D14: 45300 | E14: MEDIA HORA | F14: CALLE 14 # 13 44 | G14: BELEN | H14: SE REALIZA CONTROL DE ABEJAS POR AFETACION A UNA VIVIENDA SIENDO CATURADAS Y LIBERADAS EN LAS AFUERA DEL MUNICIPIO | I14: 0 | J14: 2 | K14: L-2
A15: INCENDIOS | B15: INCENDIO FORESTAL | D15: 45301 | E15: VEINTE MINUTOS | F15: KR 10#7-27 | G15: EL GUASIMO | H15: QUEMA CONTROLADA POR EL DUEÑO DEL PREVIO | I15: NO APLICA | J15: 3 | K15: B-4
A16: RESCATES | B16: EXTRICACIÓN VEHICULAR | D16: 45301 | E16: DOS HORAS | F16: VIA TORO ANSERMANUEVO | G16: SANPACHO | H16: PERSONA ATRAPADA POR ACCIDENTE DE TRANSITO | I16: NO APLICA | J16: 4 | K16: L-2
A17: RESCATES | B17: RESCATE DE ANIMAL | D17: 45301 | E17: UNA HORA Y SEIS MINUTOS | F17: HOSPITAL GONZALO CONTRERAS | G17: SAN PEDRO | H17: RESCATE ANIMAL ATRAPADO EN EL AREA DE LAVANDERIA | I17: NO APLICA | J17: 3 | K17: L-2
A18: RESCATES | B18: CONTROL DE ABEJAS | D18: 45292 | E18: UNA HORA Y QUINCE MINUTOS | F18: MZ F CS 3 | G18: PRADOS DEL NORTE | H18: SE ENCUENTRA ENJAMBRE DE ABEJAS A LA ENTRADA DE UNA VIVIENDA | I18: VIVIENDA | J18: 4 | K18: B-4, L-2
A19: RESCATES | B19: CONTROL DE ABEJAS | D19: 45302 | E19: 2 HORAS | F19: SECTOR ESCOMBRERA | G19: GUASIMO | H19: ATAQUE DE ABEJAS, ENJAMBRE NO ENCONTRADO | I19: CASAS ALEDAÑAS | J19: 8 | K19: B-3, L-2
A20: RESCATES | B20: CONTROL DE ABEJAS | D20: 45302 | E20: DOS HORAS Y VEINTE MINUTOS | F20: CARRERA 10#3-122 | G20: EL GUASIMO | H20: ATAUE DE ABEJAS | I20: NO APLICA | J20: 8 | K20: B-3, L-2
A21: INCENDIOS | B21: INCENDIO FORESTAL | D21: 45302 | E21: UNA HORA Y 20 MINUTOS | F21: SECTOR LA ISLA | G21: LA ISLA | H21: QUEMA QUE SE SALE DE CONTROL | I21: 2 PLAZAS | J21: 5 | K21: B-4, L-2
A22: RESCATES | B22: CONTROL DE ABEJAS | D22: 45304 | E22: TRES HORAS | F22: SECTOR EL GUASIMO | G22: EL GUASIMO | H22: ATAQUE DE ABEJAS | I22: CARRETERA | J22: 5 | K22: B-3, L-2
A23: OTROS | B23: MATERIALES PELIGROSOS / DERRAMES | D23: 45305 | E23: 2 HORAS 20 MINUTOS | F23: SABANAZO | G23: SABANAZO | H23: CHOQUE DE DOS VEHICULOS CON DERRAME DE COMBUSTIBLE | I23: 0 | J23: 5 | K23: B-4, L-2
A24: OTROS | B24: CONTROL DE ABEJAS | D24: 45305 | E24: UNA HORA . | F24: CALL 15 # 12 48 | G24: CENTRO | H24: SE REALIZA CONTROL DE ABEJAS REALIZANDO CATURA Y LIBERANDOLAS A LAS AFUERAS DEL MUNICIPIO | I24: 0 | J24: 3 | K24: B-4
A25: RESCATES | B25: RESCATE DE PERSONA / PARAPENTE | D25: 45306 | E25: DOS HORAS Y MEDIA | F25: FINCA DE GUSTAVO RAMIREZ | G25: EL RINCON | H25: SE REALIZA RESCATE DE PERSONA DE SETENTA AÑOS QUE CAE DE UN PALO DE MANGO Y RUEDA APROXIMADAMNTE 6 METROS Y SE SACO HASTA LA CARRETERA DONDE LLEGAN LOS VEHICULOS EN CAMILLA Y SE TRASLADO EN LA AMBULANCIA DE SUDSALUD AL HOSPITAL GONZALO CONTRERAS | I25: 0 | J25: 5 | K25: L-1, L-2
A26: OTROS | B26: FUGA DE GAS NATURAL | D26: 45307 | E26: HORA Y MEDIA | F26: CALE 16 5 32 | G26: LAS LAJAS | H26: SE AHCE ACORDONAMIENTO Y PRENVENCIO HASTA QUE LLEGA EL TECNICO DE GASES DE OCCIDENTE PARA SU DEBIDO CONTROL | I26: 0 | J26: 3 | K26: B-4
A27: RESCATES | B27: RESCATE DE PERSONA / PARAPENTE | D27: 45306 | E27: 2.25 HORAS | F27: VEREDA EL RINCON | G27: VEREDA EL RINCON | H27: PERSONA QUE CAE DESDE UN ARBOL,RODANDO 6 MT APROX, SE RECIBE APOYO DEAMBULANCIA DE SUB SALUD | I27: * | J27: 5 | K27: L-2, OTROS
A28: OTROS | B28: SUMINISTROS DE AGUA | D28: 45308 | E28: DOS HORAS | F28: PARQUE DE SAN LUIS | G28: SAN LUIS | H28: SE RIEGA EL PRADO DE SAN LUIS POR EXEQUIA | I28: 0 | J28: 2 | K28: B-1
A29: INCENDIOS | B29: INCENDIO FORESTAL | D29: 45308 | E29: MEDIA HORA | F29: LA ESCOMBRERA | G29: GUASIMO | H29: AL LLEGAR AL SITIO SE OBSERBA A UN SEÑOR QUE ESTA QUEMANDO UN COBRE SE LE DAN RECOMENDACIONES Y SE REGRESA ALA CUARTEL | I29: 0 | J29: 3 | K29: B-4
A30: INCENDIOS | B30: INCENDIO FORESTAL | D30: 45309 | E30: 7 MIN | F30: PEDREGAL, CIA TORO - LA UNIÓN | H30: INCENDI FORESTAL QUE CONTROLA LA COMUNIDAD | I30: N/A | J30: 3 | K30: B-4
A31: INSPECCIONES DE SEGURIDAD | B31: LABORES DE PREVENCION O ACOMPAÑAMIENTO EN GESTION DEL RIESGO | D31: 45310 | E31: 1 HORA | F31: VEREDA MARTINDOZA | H31: INSPECCIONES POR MOVIMIENTO TELURICO | I31: N/A | J31: 2 | K31: L-2
A32: OTROS | B32: CONTROL DE ABEJAS | D32: 45310 | E32: UNA HORA | F32: KARRERA 9 VIA LAS PALMAS | G32: LAS PALAMAS | H32: ATAQE DE ABEJAS | I32: NO APLICA | J32: 5 | K32: L-2
A33: INSPECCIONES DE SEGURIDAD | B33: LABORES DE PREVENCION O ACOMPAÑAMIENTO EN GESTION DEL RIESGO | D33: 45310 | E33: UNA HORA CON TREINTA | F33: COLEGIO SANJOSE YIGLESIA SANJOSE | G33: CENTRO | H33: REVICION POR TEMBLOR | I33: NO APLICA | J33: 2 | K33: L-2
A34: INCENDIOS | B34: RESCATE DE PERSONA / PARAPENTE | D34: 45312 | E34: 0.10277778 | F34: VIA A SABANAZO POR LA CRUZ BLANCA | G34: SANPEDRO | H34: INCENDIO FORESTAL | I34: NO ESPECIFICA | J34: 7 | K34: B-1, B-4
A35: BUSQUEDA Y RESCATE | B35: RESCATE DE PERSONA / PARAPENTE | D35: 45313 | E35: CUATRO HORAS CON DIEZ MINUTOS | F35: BASE MILITAR LA FLORIDA TORO | G35: TORO VALLE | H35: APOYO RESCATE PARAPENTISTA EN TORO | I35: NO APLICA | J35: 5 | K35: L-2
A36: INCENDIOS | B36: INCENDIO FORESTAL | D36: 45313 | E36: UNA HORA | F36: INCENDIO FORESTAL VIA TORO | G36: PEDREGAL | H36: INCENDIO FORESTAL POR PEDREGAL | I36: 45323 | J36: 2 | K36: B-4
A37: OTROS | B37: CONTROL DE ABEJAS | D37: 45313 | E37: VEINTE MINUTOS | F37: DROGUERIA SUPER DROGAS EN LA CALLE 14 | G37: CENTRO | H37: ABEJAS EN LA PARTE EXTERNA DE LA DROGUERIA | I37: NO APLICA | J37: 4 | K37: B-3
A38: INCENDIOS | B38: INCENDIO FORESTAL | D38: 45314 | E38: DOS HORAS CON CINCO MINUTOS | F38: PAJARO DE ORO | G38: PAJARO DE ORO VIA EL TIGRE | H38: INCENDIO FORESTAL EN PAJARO DE ORO VIA EL TIGRE | I38: 500 MTS | J38: 6 | K38: L-1, L-2
A39: INCENDIOS | B39: INCENDIO FORESTAL | D39: 45314 | E39: VEINTIDOS MUNUTOS | F39: KR 19 CON CALLE 21 | G39: SANPEDRO | H39: QUEMA CONTROLADA | I39: NO ESPECIFICA | J39: 3 | K39: B-4
A40: INCENDIOS | B40: INCENDIO FORESTAL | D40: 45314 | E40: CUATRO HORAS CON VEINTE MINUTOS | F40: EL PICACHO | G40: VIA LA UNION ROLDANILLO | H40: QUEMA FORESTAL VIA LA UNION ROLDANILLO POR EL PICACHO | I40: 37.771 MTS | J40: 14 | K40: B-1, B-4, L-1, L-2
...

Sheet 2023
A1: TIPO DE INCIDENTE | B1: INCIDENTES Y ACTIVIDADES | C1: CANTIDAD DE | D1: DÍA DEL EVENTO | E1: DURACIÓN DEL EVENTO | F1: DIRECCIÓN O LUGAR DE REFERENCIA | G1: BARRIO CORREGIMIENTO O VEREDA | H1: DESCRIPCIÓN DEL EVENTO | I1: N° DE UNIDADES QUE ASISTIERON | J1: VEHÍCULO | U1: COLAPSO DE ESTRUCTURAS | V1: COLAPSO DE TECHOS | W1: CAPACITACIONES | X1: DERRAME DE COMBUSTIBLE O ACEITES | Y1: ENTRENOS | Z1: FUGA DE GAS NATURAL | AA1: FUGA DE GAS GLP | AB1: INCENDIO FORESTAL | AC1: INCENDIO ESTRUCTURAL | AD1: INCENDIO VEHICULAR | AE1: INUNDACIÓN | AF1: LABORES DE PREVENCION | AG1: MATERIALES PELIGROSOS | AH1: PRIMEROS AUXILIOS | AI1: RESCATE DE PERSONA | AJ1: RECATE DE PARAPENTE | AK1: RESCATE DE ANIMAL | AL1: REUNIÓN EN LA ALCALDÍA | AM1: REUNIÓN DE CMGRD | AN1: REUNIÓN DE OFICIALES | AO1: REUNIONES DE SERVICIO SOCIAL | AP1: SUMINISTROS DE AGUA | AQ1: SUMINISTRO DE AGUA O LABORES COVID-19 | AR1: VISITAS DE ANÁLISIS DE RIESGOS | AS1: VISITAS DE SEGURIDAD
C2: ='DETALLADO X MES 2026'!J2 -> INCENDIO FORESTAL
A3: ENERO
A4: OTROS | B4: FUGA DE GAS NATURAL | C4: =COUNTIF(B4:B38,$C$2) -> 6 | D4: 44928 | E4: HORA Y VEINTE | F4: URB LAS PALMAS | G4: LAS PALMAS | H4: SE REALIZA CONTROL DE FUGA POR ROTURA DE TUBO EN ESCABACION | I4: 3 | J4: B-2
A5: INSPECCIONES DE SEGURIDAD | B5: VISITAS DE SEGURIDAD | D5: 44930 | E5: HORA Y MEDIA | F5: LATORRE BARBE SHOP | G5: EL JARDIN | H5: ANALICES DE RIESGO A ESTABLECIMIENTO | I5: 1 | J5: L-3
A6: INSPECCIONES DE SEGURIDAD | B6: VISITAS DE SEGURIDAD | D6: 44931 | E6: 1:30 MINUTOS | F6: CL 15 # 14-70 | G6: CENTRO | H6: VISITA DE SEGURIDAD | I6: 1 | J6: OTROS
A7: OTROS | B7: CONTROL DE ABEJAS | D7: 44932 | E7: HORA Y CUARTO | F7: CRR 15 VIA AL LUCERO | G7: EL LUCERO | H7: SE REALIZA RECUPERACION DE ABEJAS EN LA URBANIZACION MORADA DEL VIENTO | I7: 3 | J7: B-3
A8: RESCATES | B8: RESCATE DE PERSONA / PARAPENTE | D8: 44941 | E8: UNA HORA | F8: FINCA GRAJALES | G8: BARRIO LAS LAJAS | H8: PERSONA QUE CAE EN SU PARAPENTE | I8: 8 | J8: B-3, L-2
A9: INSPECCIONES DE SEGURIDAD | B9: VISITAS DE SEGURIDAD | D9: 44942 | E9: 1 HORA | F9: TIENDA D1 | G9: CENTRO | H9: INSPECCION DE SEGURIDAD POR SEGUNDA VEZ, VERIFICACION DE LOS REQUISITOS SOLICITADOS EN LA 1RA INSPECCION | I9: 1 | J9: OTROS
A10: RESCATES, OTROS | B10: CONTROL DE ABEJAS | D10: 18/01/0023 | E10: 40 MNTOS | F10: CRA 20 16-37 | G10: EL JARDIN | H10: VERIFICACION CONTROL ABEJAS | I10: 2 | J10: L-2
A11: OTROS | B11: CONTROL DE ABEJAS | D11: 44945 | E11: 29 MNTOS | F11: ZONA ROSA DISCOTK SEVEN | G11: CALLE 15 CRA 5 ESQ | H11: VERIFICACION ENJAMBRE DE ABEJAS | I11: 3 | J11: L-2
A12: INSPECCIONES DE SEGURIDAD | B12: VISITAS DE SEGURIDAD | D12: 44945 | E12: 1 HORA 30 MINUTOS | F12: COMERCIO DEL MUNICIPIO | H12: INSPECCION DE SEGURIDAD AL COMERCIO DEL MUNICIPIO | I12: 1 | J12: L-3
A13: INSPECCIONES DE SEGURIDAD | B13: VISITAS DE SEGURIDAD | D13: 44946 | E13: 2 HORAS | F13: COMERCIO DEL MUNICIPIO | H13: DOS INSPECCIONES DE SEGURIDAD AL COMERCIO DEL MUNICIPIO | I13: 1 | J13: L-2
A14: INCENDIOS | B14: INCENDIO FORESTAL | D14: 44946 | E14: 1 HORA 30 MINUTOS | F14: EL GUASIMO VIA SANTA ELENA | G14: SANTA ELENA | H14: INCENDIO EN RESIDUOS DE MATERA LATERAL A LA VIA, QUE GENERABA RIESGO DE PROPAGARSE POR LA LADERA | I14: 6 | J14: B-2, L-2
A15: OTROS | B15: CONTROL DE ABEJAS | D15: 44946 | E15: 29 MNTOS | F15: DISCOTEK SEVEN | G15: LAS LAJAS | H15: DESPLAZAMIENTO NO SE PUDO REALIZAR EL CONTROL | I15: 3 | J15: L-2
A16: INCENDIOS | B16: INCENDIO FORESTAL | D16: 44947 | E16: 1 HORA | F16: LUCERO ALTO | H16: QUEMA DE PASTIZAL Y SINGLA CON AFECTACION DE CULTIVO DE UVA | I16: 7 | J16: B-2, B-4
A17: OTROS | B17: CAÍDA / CORTES DE ARBOL | D17: 44948 | E17: 2.20HORAS | F17: VIA SABANAZO | G17: VIA SABANAZO | H17: RAMA DE UN ARBOL QUE ESTA SOBRE LA VIA | I17: 3 | J17: L-2
A18: OTROS | B18: CONTROL DE AVISPAS | D18: 44949 | E18: UNA HORA Y QUINCE MINUTOS | F18: CRR 16 9 43 | G18: CAMPO ALEGRE | H18: SE HACE RECUPERACION DE AVISPAS Y SE LIBERAN EN UN LUGAR FUERA DEL MUNICIPIO | I18: 3 | J18: B-2
A19: OTROS | B19: CONTROL DE ABEJAS | D19: 44949 | E19: DOS HORAS Y MEDIA | F19: MARTINDOZA | G19: MARTINDOZA | H19: SE REALIZA RECUPERACION DE LAS ABEJAS Y SE LLEVAN A LAS AFUERA DEL MUNICIPIO | I19: 2 | J19: L-2
A20: INSPECCIONES DE SEGURIDAD | B20: VISITAS DE SEGURIDAD | D20: 44950 | E20: 2 HORAS | F20: COMERCIO DEL MUNICIPIO | H20: 3 VISITAS DE ANALISI DE RIESGOS COMERCIO DEL MUNICIPIO | I20: 1 | J20: OTROS
A21: INSPECCIONES DE SEGURIDAD | B21: VISITAS DE SEGURIDAD | D21: 44950 | E21: 1.15 HORAS | F21: CALLE16 3-51 | G21: LAS LAJAS | H21: VISITA DE SEGURIDAD LICORES BAR EL CHAPO | I21: 1 | J21: L-1
A22: INSPECCIONES DE SEGURIDAD | B22: VISITAS DE SEGURIDAD | D22: 44950 | E22: 1 HORA | F22: CALLE 16 4-14 | G22: LAS LAJAS | H22: VISITA DE SEGURIDAD LICORES PUNTO CLAVE | I22: 1 | J22: L-1
A23: INSPECCIONES DE SEGURIDAD | B23: VISITAS DE SEGURIDAD | D23: 44950 | E23: 1 .20 HORAS | F23: CRA 3 14-13 | G23: LAS LAJAS | H23: VISITA DE SEGURIDAD ALMACEN AGRODISTRIBUIDORA EL CAMPO | I23: 1 | J23: L-1
A24: INSPECCIONES DE SEGURIDAD | B24: VISITAS DE SEGURIDAD | D24: 44951 | E24: 1 HORA | F24: CALLE 14 13 82 | G24: BELEN | H24: VISITA DE SEGURIDAD ALMACEN UNICELL | I24: 1 | J24: OTROS
A25: INSPECCIONES DE SEGURIDAD | B25: VISITAS DE SEGURIDAD | D25: 44951 | E25: 1.30HORAS | F25: CRA 15 19 154 | G25: BELEN | H25: VISITA DE SEGURIDAD TIENDA MEDICA LA UNION | I25: 1 | J25: OTROS
A26: INSPECCIONES DE SEGURIDAD | B26: VISITAS DE SEGURIDAD | D26: 44951 | E26: 1 HORA 30 MINUTOS | F26: COMERCIO DEL MUNICIPIO | H26: 2 INSPECCIONES DE SEGURIDAD Y ANALISIS DE RIESGOS AL COMERCIO | I26: 1 | J26: L-1
A27: INCENDIOS | B27: INCENDIO FORESTAL | D27: 44953 | E27: 30 MINUTOS | F27: CR 16 CON CALLE 2 FRENTE A LA ESTACION LAS LAJAS | H27: INCENDIO FORESTAL EN UN POTRERO | I27: 4 | J27: B-2
A28: INSPECCIONES DE SEGURIDAD | B28: VISITAS DE SEGURIDAD | D28: 44953 | E28: 1 HORA 30 MINUTOS | F28: SAN PEDRO | G28: SAN PEDRO | H28: VISITA DE SEGURIDAD | I28: 1 | J28: L-1
A29: RESCATES | B29: RESCATE DE PERSONA / PARAPENTE | D29: 44954 | E29: 30 MINUTOS | F29: POR EL CARMEN | G29: EL RINCON | H29: PARAPENTE QUE CAE AL SUELO PERO SALE POR SU PROPIOS MEDIOS | I29: 7 | J29: L-1, L-2
A30: INCENDIOS | B30: INCENDIO FORESTAL | D30: 44954 | E30: 2 HORAS | F30: TEJEDA | G30: TEJEDA | H30: INCENDIO RESIDUOS DE CAÑA | I30: 9 | J30: B-2, B-4, L-2
A31: INCENDIOS | B31: INCENDIO FORESTAL | D31: 44954 | E31: 1 HORA | F31: TEJEDA | G31: TEJEDA | H31: SE REATIVO EL INCENDIO | I31: 4 | J31: B-2
A32: INCENDIOS | B32: INCENDIO FORESTAL | D32: 44954 | E32: 1.37 HORAS | F32: BODEGAS DE EDUARDO JIMENEZ | G32: CORSEGA | H32: REFRIGERACION DE FOCOS DE UNA QUEMA DE DESECHOS AGRICOLAS CAÑA QUE SE REINICIAN NUEVAMENTE | I32: 4 | J32: B-2
A33: OTROS | B33: CONTROL DE AVISPAS | D33: 44955 | E33: 30 MNTOS | F33: CALLE 16 CRA 13 ESQ | G33: POPULAR | H33: DESPLAZAMIENTO AL SITIO A VERIFICAR | I33: 2 | J33: B-3
A34: OTROS | B34: FUGA DE GAS NATURAL | D34: 44956 | E34: MEDIA HORA | F34: CARRERA 15 # 22 72 | G34: SAN PEDRO | H34: AL LLEGAR AL SITIO SE ENCUENTRA ROTURA DE TUBO DE GAS NATURAL SE HACE PREVENCION MIENTRAS LLEGA EL FUNCIONARIO DE GASES DE OCCIDENTE | I34: 4 | J34: B-2
A35: OTROS | B35: CONTROL DE ABEJAS | D35: 44956 | E35: 2 HORAS | F35: COLEGIO ITDG | G35: URB EL AMPARO | H35: ENJAMBRE DE ABEJAS QUE LLEGA A UN ARBOL EN LA CANCHA DEL COLEGIO | I35: 3 | J35: L-2
A36: OTROS | B36: CONTROL DE ABEJAS | D36: 44956 | E36: 40 MNTOS | F36: CRA 14 6 01 | G36: BELEN | H36: TRASLADO DE ENJAMBRE QUE ESTABA EN LA ESTACION DE BOMBEROS AL SECTOR DE LA ISLA | I36: 3 | J36: L-2
A37: OTROS | B37: LABORES DE PREVENCION O ACOMPAÑAMIENTO EN GESTION DEL RIESGO | D37: 44937 | E37: 24 MNTOS | F37: LA CAMPESINA BAJA | G37: CAMPESINA BAJA | H37: MONOTOREO QUEBRADA SAN PEDRO SECTOR LA CAMPESINA | I37: 4 | J37: L-2
A38: OTROS | B38: LABORES DE PREVENCION O ACOMPAÑAMIENTO EN GESTION DEL RIESGO | D38: 44937 | E38: 20 MNTOS | F38: PUENTE CRA 15 | G38: LA CIUDADELA | H38: MONITOREO QUEBRADA LA UNION | I38: 4 | J38: L-2
A39: FEBRERO
A40: INSPECCIONES DE SEGURIDAD | B40: VISITAS DE SEGURIDAD | C40: =COUNTIF(B40:B99,$C$2) -> 4 | D40: 44958 | E40: 2.30 HORAS | F40: CRA 15 CALLE 17 ESQ | G40: POPULAR | H40: VISITA DE SEGURIDAD | I40: 1 | J40: L-1
...

Sheet 2022
A1: TIPO DE INCIDENTE | B1: INCIDENTES Y ACTIVIDADES | C1: CANTIDAD DE | D1: DÍA DEL EVENTO | E1: DURACIÓN DEL EVENTO | F1: DIRECCIÓN O LUGAR DE REFERENCIA | G1: BARRIO CORREGIMIENTO O VEREDA | H1: DESCRIPCIÓN DEL EVENTO | I1: N° DE UNIDADES QUE ASISTIERON | J1: VEHÍCULO
C2: ='DETALLADO X MES 2026'!J2 -> INCENDIO FORESTAL
A3: ENERO
A4: INCENDIOS | B4: INCENDIO ESTRUCTURAL | C4: =COUNTIF(B4:B22,C2) -> 3 | D4: 44567 | E4: 1 | F4: CLL 13 | G4: V | H4: Simulación | I4: 1 | J4: M-1
A5: OTROS | B5: CONTROL DE AVISPAS | D5: 08/01/0022 | E5: 2 H | F5: PARQUE PRINCIPAL | G5: CENTRO | H5: CONTROL DE AVISPAS | I5: 5 | J5: M-2, M-3
A6: RESCATES | B6: RESCATE DE ANIMAL | D6: 44571 | E6: 30 minutos | F6: GALERIA EN EL ALMACEN EL VAQUERO | H6: GATO QUE SE ENCUENTRA EN UN TEJADO | I6: 3 | J6: M-2
A7: RESCATES | B7: RESCATE DE ANIMAL | D7: 44572 | E7: 30 MINUTOS | F7: GALERIA - ALMACEN EL VAQUERO | H7: GATO EN UN TEJADO PERO POR SE MUR ARISCO NO SE DEJO COJER | I7: 2 | J7: M-2
A8: INCENDIOS | B8: INCENDIO FORESTAL | D8: 44577 | E8: 1 H | F8: SANTAELENA | H8: INFORMAN LA PRESENCIA DE FOCOS DE INCENDIOS EN LA MONTAÑA | I8: 6 | J8: M-2
A9: MATERIALES PELIGROSOS | B9: FUGA DE GAS NATURAL | D9: 44583 | E9: UNA HORA | F9: CALLE 13 # 20-198 | G9: LA CRUZ | H9: FUGA DE GAS EN VIA PUBLICA | I9: 3 | J9: M-2
A10: OTROS | B10: CONTROL DE AVISPAS | D10: 44586 | E10: 5 H | F10: PARQUE PRINCIPAL | H10: CONTROL DE AVISPAS | I10: 6 | J10: M-3, M-6
A11: OTROS | B11: CAÍDA / CORTES DE ARBOL | D11: 44590 | E11: 4 H | F11: VIA LA VICTORIA | H11: CORTE DE ARBOL | I11: 5 | J11: M-2, M-6
A12: INCENDIOS | B12: INCENDIO FORESTAL | D12: 44591 | E12: 1 H | F12: VIA SABANAZO A LA ALTURA DE LA BALASTRERA | H12: INCENDIO A CAUSA DE LA QUEMA DE BASURAS | I12: 4 | J12: M-2
A13: OTROS | B13: CAÍDA / CORTES DE ARBOL | D13: 44592 | E13: CUARENTA MINUTOS | F13: FRENTE AL PARQUEADERO LAS LAJAS | G13: LAS LAJAS | H13: RAMA DE ARBOL QUE CAE SOBRE LA VIA PUBLICA ENTRADA AL MUNICIPIO | I13: 2 | J13: M-4
A14: OTROS | B14: PRIMEROS AUXILIOS | D14: 44570 | E14: 3 HORAS | F14: VIA SABANAZO | H14: MOTOCICLISTAQUE SE SALIO DE LA VIA | I14: 11 | J14: M-3, M-5
A15: RESCATES, OTROS | B15: RESCATE DE PERSONA / PARAPENTE | D15: 44580 | E15: 1 HORA | F15: FINCA LAS CAMELIAS | G15: PAJARO DE ORO | H15: PARAPENTE QUE QUEDO ATRAPADO EN UN ARBOL | I15: 11 | J15: M-3, M-4
A16: INSPECCIONES DE SEGURIDAD | B16: VISITAS DE SEGURIDAD | D16: 44580 | E16: 2 HORAS | F16: ESTANQUILLO JJ | H16: VISITA DE SEGURIDAD | I16: 2 | J16: M-4
A17: INSPECCIONES DE SEGURIDAD | B17: VISITAS DE SEGURIDAD | D17: 44580 | E17: 2 HORAS | F17: ESTANQUILLO LA 16 | H17: VISITA DE SEGURIDAD | I17: 2 | J17: M-4
A18: BUSQUEDA Y RESCATE | B18: RESCATE DE PERSONA / PARAPENTE | D18: 44582 | E18: 1 HORA | F18: SANTA ELENA | G18: HIGUERONCITO | H18: RESCATE DE PARAPENTE EN LA PARTE ALTA DE LA MONTAÑA | I18: 8 | J18: M-3, M-4
A19: INCENDIOS | B19: LABORES DE PREVENCION O ACOMPAÑAMIENTO EN GESTION DEL RIESGO | D19: 44588 | E19: 1 HORA | F19: SANTA ELENA | G19: HIGUERONCITO | H19: SALE UNA CUADRILLA PARA VERIFICAR-- DE DEVUELVEN POR QUE SE EXTINGUIO SOLO | I19: 5 | J19: M-4
A20: INCENDIOS | B20: INCENDIO FORESTAL | D20: 44592 | E20: 1 HORA | F20: VIA SABANAZO | H20: QUEMA DE UN BASURERO QUE FUE CONTROLADO Y LIQUIDADO | I20: 4 | J20: M-2
A21: OTROS | B21: CAÍDA / CORTES DE ARBOL | D21: 44592 | E21: 40 MINUTOS | F21: CALLE 16 ENTRADA AL MUNICIPIO | H21: RAMA QUE CAE A LA VIA OSTACULIZA EL PASO VEHICULAR | I21: 2 | J21: M-4
A22: INSPECCIONES DE SEGURIDAD | B22: VISITAS DE SEGURIDAD | D22: 44576 | E22: 3 H | F22: AUDIFARMA SAS CR 14 # 13 - 22 | H22: VISITA DE SEGURIDAD | I22: 1 | J22: M-6
A23: FEBRERO
A24: MATERIALES PELIGROSOS | B24: MATERIALES PELIGROSOS / DERRAMES | C24: =COUNTIF(B24:B54,C2) -> 3 | D24: 44594 | E24: 30 MINUTOS | F24: CALLE 14 CON CARRERA 13 | G24: BELEN | H24: REGUERO DE COMBUSTIBLE EN LA VIA PUBLICA | I24: 6 | J24: M-3
A25: INCENDIOS | B25: INCENDIO FORESTAL | D25: 44595 | E25: MEDIA HORA | F25: CALL 18 # 12 09 | G25: URBANIZACION TRAS ANDINA | H25: QUE MA DE PASTIZAL EN LOTE VALDIO | I25: 5 | J25: M-2
A26: INCENDIOS | B26: INCENDIO FORESTAL | D26: 44596 | E26: UNA HORA | F26: SOBRE LA PANORAMA PASANDO EL PUENTE DE SAN LUIS | G26: CORREGIMIENTO DE SAN LUIS | H26: INCENDIO EN UN LOTE ESTABAN ASIENDO QUEMA CONTROLADA AFETANDO LAS VIENDAS CON EL HUMO | I26: 6 | J26: M-2
A27: OTROS | B27: INUNDACIÓN | D27: 44597 | E27: 30 minutos | F27: calle 13 # 8-33 | H27: vivienda inundad | I27: 3 | J27: M-2
A28: BUSQUEDA Y RESCATE | B28: RESCATE DE ANIMAL | D28: 44599 | E28: 30 MIN | F28: CLL 19 # 17 - 84 | H28: Se recibe llamado solicitando ayuda para la recuperacion de una zarigeya atrapada en el baño de una vivienda. | I28: 3 | J28: M-2
A29: INCENDIOS | B29: INCENDIO FORESTAL | D29: 44604 | E29: DOS HORAS Y MEDIA | F29: EL LUCERO | G29: FINCA EL PLACER | H29: QUEMA CONTROLADA QUE SE SALIO DEL CONTROL | I29: 6 | J29: M-2, M-4
A30: INSPECCIONES DE SEGURIDAD | B30: VISITAS DE SEGURIDAD | D30: 44600 | E30: 1 H | F30: DROGUERIA AUDIFARMA | H30: VISITA DE SEGURIDAD | I30: 1 | J30: M-4
A31: INSPECCIONES DE SEGURIDAD | B31: VISITAS DE SEGURIDAD | D31: 44600 | E31: 1 H | F31: MEGA HOGAR | H31: VISITA DE SEGURIDAD | I31: 2 | J31: M-4
A32: INSPECCIONES DE SEGURIDAD | B32: VISITAS DE SEGURIDAD | D32: 44603 | E32: 5 H | F32: STAY HIGH | H32: VISITA DE SEGURIDAD | I32: 1 | J32: M-6
A33: INSPECCIONES DE SEGURIDAD | B33: VISITAS DE SEGURIDAD | D33: 11/02/0003 | E33: 5 H | F33: CASA SHOW LOS CRISTALES | H33: VISITA DE SEGURIDAD | I33: 1 | J33: M-6
A34: INSPECCIONES DE SEGURIDAD | B34: VISITAS DE SEGURIDAD | D34: 44603 | E34: 5 H | F34: ESTANQUILLO LOS COCHOSOS PLAZA | H34: VISITA DE SEGURIDAD | I34: 1 | J34: M-6
A35: INSPECCIONES DE SEGURIDAD | B35: VISITAS DE SEGURIDAD | D35: 44599 | E35: 2 H | F35: REMATES KANUTO | H35: VISITAS DE SEGURIDAD | I35: 1 | J35: M-6
A36: INSPECCIONES DE SEGURIDAD | B36: VISITAS DE SEGURIDAD | D36: 44599 | E36: 2 H | F36: BANCO AGRARIO | H36: VISITA DE SEGURIDAD | I36: 1 | J36: M-6
A37: INSPECCIONES DE SEGURIDAD | B37: VISITAS DE SEGURIDAD | D37: 44607 | E37: 3 H | F37: COOPSER CRA 13 # 13 - 24 | H37: VISITA DE SEGURIDAD | I37: 1 | J37: M-6
A38: INSPECCIONES DE SEGURIDAD | B38: VISITAS DE SEGURIDAD | D38: 44607 | E38: 3 H | F38: CIC LABORATORIO CRA 12 # 13 - 34 | H38: VISITA DE SEGURIDAD | I38: 1 | J38: M-6
A39: INSPECCIONES DE SEGURIDAD | B39: VISITAS DE SEGURIDAD | D39: 44607 | E39: 3 H | F39: TIENDA MIXTA LICORES DEL VALLE CLL 18 #15 - 50 | H39: VISITA DE SEGURDAD | I39: 1 | J39: M-6
A40: RESCATES | B40: RESCATE DE ANIMAL | D40: 44608 | E40: 2 HORAS | F40: PARQUE PRINCIPAL | G40: PARQUE PRINCIPAL | H40: ANIMAL QUE SE ENCUENTRA EN LUGAR PUBLICO EL CUAL FUE CAPTURADO Y REHUBICADO EN SU HABITAD | I40: 4 | J40: M-3
...

Sheet 2021
A1: TIPO DE INCIDENTE | B1: INCIDENTES Y ACTIVIDADES | C1: CANTIDAD DE | D1: DÍA DEL EVENTO | E1: DURACIÓN DEL EVENTO | F1: DIRECCIÓN O LUGAR DE REFERENCIA | G1: BARRIO CORREGIMIENTO O VEREDA | H1: DESCRIPCIÓN DEL EVENTO | I1: N° DE UNIDADES QUE ASISTIERON | J1: VEHÍCULO
C2: ='DETALLADO X MES 2026'!J2 -> INCENDIO FORESTAL
A3: ENERO
A4: OTROS | B4: LABORES DE PREVENCION O ACOMPAÑAMIENTO EN GESTION DEL RIESGO | C4: =COUNTIF(B4:B27,C2) -> 4 | D4: 44197 | E4: 48 MINUTOS | F4: CALLE 13 #20-08 | G4: LA CRUZ | H4: SE LE COLABORA AL SEÑOR EVER HUMBERTO GOMEZ PARA ABRIR UNA PUERTA YA QUE QUE SE LE PARTIERON LAS LLAVES Y HUBO QUE ENTRAR POR LA PARTE DEL SEGUNDO PISO | I4: 2 | J4: M-2
A5: OTROS | B5: INUNDACIÓN | D5: 44197 | E5: 1 HORA 33 MINUTOS | F5: CALLE 12 A #23A 04 | G5: PASOANCHO | H5: SE PRESTA EL AUXULIO DE LAVADO EN LA CASA DE LA SEÑORA MARCELA MONSALVE VELASQUEZ YA QUE POR FUERTE AGUACERO HUBO REVOSE DE LAS ALCANTARILLAS | I5: 3 | J5: M-2
A6: INSPECCIONES DE SEGURIDAD | B6: VISITAS DE SEGURIDAD | D6: 44200 | E6: 1 HORA | F6: CENTRO | H6: SE HACE INSPECION EL ALMACEN F Y O NUTRICION CELULAR DEL VALLE | I6: 1 | J6: M-6
A7: INSPECCIONES DE SEGURIDAD | B7: VISITAS DE SEGURIDAD | D7: 44202 | E7: DOS HORAS | F7: PARQUE PRINCIPAL | H7: INSPECION DE SEGURIDAD | I7: 1 | J7: M-6
A8: INSPECCIONES DE SEGURIDAD | B8: VISITAS DE SEGURIDAD | D8: 44202 | E8: 1 HORA 10 MINUTOS | F8: CENTRO | H8: SE HACE INSPECION EN EL ESTABLECIMIENTO COFINCAFE | I8: 1 | J8: M-6
A9: INSPECCIONES DE SEGURIDAD | B9: VISITAS DE SEGURIDAD | D9: 44202 | E9: 1 HORA 10 MIUTOS | F9: CENTRO | H9: SE HACE INSPECION EN EL PIQUETEADERO MILLAN | I9: 1 | J9: M-6
A10: INSPECCIONES DE SEGURIDAD | B10: VISITAS DE SEGURIDAD | D10: 44203 | E10: DOS HORAS | F10: CENTRO | H10: VISITA DE SEGURIDAD | I10: 1 | J10: M-6
A11: OTROS | B11: LABORES DE PREVENCION O ACOMPAÑAMIENTO EN GESTION DEL RIESGO | D11: 44203 | E11: DOS HORS CON CUARENTA Y CINCO | F11: PARQUE PRINCIPAL LA UNION VALLE | G11: PARQUE PRINCIPAL | H11: PREVENCION CON TRANSITO Y CONVIVENCIA CIUDADANA SOBRE USO DE TAPABOCAS | I11: 1 | J11: OTROS
A12: OTROS | B12: LABORES DE PREVENCION O ACOMPAÑAMIENTO EN GESTION DEL RIESGO | D12: 44204 | E12: DOS HORAS CON TREINTA MINUTOS | F12: PARQUE PRINCIPAL | H12: PREVENCION SOBRE COVID 19 | I12: 1 | J12: M-6
A13: OTROS | B13: LABORES DE PREVENCION O ACOMPAÑAMIENTO EN GESTION DEL RIESGO | D13: 44204 | E13: 2 HORAS | F13: CENTRO | H13: SE HACE ACOMPAÑAMIENTO EN LAVORES DE PREVENCION COVID CON LA ALCALDIA EN EL PARQUE | I13: 1 | J13: OTROS
A14: INSPECCIONES DE SEGURIDAD | B14: VISITAS DE SEGURIDAD | D14: 44208 | E14: 2 horas | F14: FINCA LA ISABELA | G14: KL 1 VIA SAN LUIS | H14: VISITA DE SEGURIDAD | I14: 1 | J14: M-6
A15: INSPECCIONES DE SEGURIDAD | B15: VISITAS DE SEGURIDAD | D15: 44208 | E15: 2 HORAS | F15: KOBA COLOMBIA SAS | G15: KL 1 VIA LA UNION SANLUIS | H15: VISITA DE SEGURIDAD | I15: 1 | J15: M-6
A16: INSPECCIONES DE SEGURIDAD | B16: VISITAS DE SEGURIDAD | D16: 44208 | E16: 30 MINUTOS | F16: ALMACEN RANA | G16: CLL 16 CON CR 7 | H16: VISITA DE SEGURIDAD | I16: 1 | J16: M-6
A17: INCENDIOS | B17: INCENDIO FORESTAL | D17: 44209 | E17: 2 HORAS | F17: FINCA LA LLAVE AMARILLA | G17: CAMPESINA BAJA | H17: INCENDIO FORESTAL | I17: 7 | J17: M-2, M-3
A18: MATERIALES PELIGROSOS | B18: FUGA DE GAS NATURAL | D18: 44210 | E18: 1 HORA | F18: CRA 12 CON CALLE 16 | G18: POPULAR | H18: SE PRESENTA FUGA DE GAS NATURAL POR TRABAJOS EN LA VIA ,SE HACE LAVORES DE PREVENCION MIENTRAS LLEGA EL TECNICO DE GASES DE OCCIDENTE | I18: 6 | J18: M-2
A19: MATERIALES PELIGROSOS | B19: FUGA DE GAS NATURAL | D19: 44210 | E19: 1 HORA | F19: URBANIZACION PRADOS DEL NORTE | G19: PRADOS DEL NORTE | H19: SE HACEN LAVORES DE PREVENCION EN EL SITIO MIENTRAS LLEGABA EL TECNICO DE GASES DE OCCIDENTE ROPTURA PRESENTADA POR TRABAJOS EN LA VIA | I19: 6 | J19: M-2, M-3
A20: INSPECCIONES DE SEGURIDAD | B20: VISITAS DE SEGURIDAD | D20: 44210 | E20: 1 HORA | F20: AUDIFARMA | H20: VISITA DE SEGURIDAD | I20: 1 | J20: M-6
A21: INCENDIOS | B21: INCENDIO FORESTAL | D21: 44211 | E21: 2 HORAS | F21: FINCAS LAS MARIAS | G21: CAMPESINA BAJA | H21: INCENDIO FORESTAL DE MATERIAL VEJETAL | I21: 5 | J21: M-2
A22: INSPECCIONES DE SEGURIDAD | B22: VISITAS DE SEGURIDAD | D22: 44215 | E22: UNA HORA | F22: PARQUE PRINCIPAL | H22: INSPECION DE SEGURIDAD | I22: 1 | J22: M-6
A23: INSPECCIONES DE SEGURIDAD | B23: VISITAS DE SEGURIDAD | D23: 44215 | E23: UNA HORA | F23: (C I C ) LABORATORIO CENTRO | H23: INSPECION DE SEGURIDAD | I23: 1 | J23: M-6
A24: RESCATES | B24: RESCATE DE PERSONA / PARAPENTE | D24: 44221 | E24: UNA HORA | F24: CANCHA AUXILIAR DEL ESTADIO | G24: BARRIO BELEN | H24: PARAPENTISTA QUE QUEDA ENREDADO EN UN ARBOL | I24: 6 | J24: M-2
A25: INSPECCIONES DE SEGURIDAD | B25: VISITAS DE SEGURIDAD | D25: 44225 | E25: UNA HORA CUARENTE MINUTOS | F25: PARQUE PRINCIPAL CENTRO | H25: INSPECION DE SEGURIDAD EN ALMACEN DE ELECTRODOMESTICOS | I25: 1 | J25: M-6
A26: OTROS | B26: INCENDIO FORESTAL | D26: 44226 | E26: 33 MINUT | F26: CHALET ELAMPARO | G26: VIA A TORO | H26: INCENDIO QUEMA DE PASTIZAL | I26: 4 | J26: M-2
